
# Created by Ruins mod Ingame Parser
# authoring Player: Syndaryl

# TEMPLATE PARAMETER SETTINGS:
#
# criterion expression specifying mod ids required to load template
# may include plus (AND), minus (AND NOT), comma (OR), and parentheses
# all required mods listed must be present; no prohibited mods can be
requiredMods=
#
# likelihood this template will be chosen relative to all others
# e.g., a weight=6 template is chosen 3X as often as one with weight=2
weight=1
#
# list of dimensions in which this template may spawn, even if generic
# one or more dimension names, separated by commas (blank = all)
dimensionsToSpawnIn=
#
# list of other biomes in which this template may spawn
# biome corresponding to directory is always assumed, listed or not
# generic templates should leave this list empty
biomesToSpawnIn=
#
# criterion expression specifying types of biome where template spawns
# this is in addition to those explicitly listed as biomesToSpawnIn
# generic templates should leave this list empty
biomeTypesToSpawnIn=FOREST,PLAINS,HILLS
#
# list of biomes in which this template may not spawn
# takes precedence over biomeTypesToSpawnIn, but NOT biomesToSpawnIn
# should be empty if biomeTypesToSpawnIn is empty
biomesToNotSpawnIn=
#
# depth template is pushed down into the surface when built
# offset is min/max range of random additional bury depth
embed_into_distance=1
random_height_offset=0,0
#
# whitelist/blacklist of block states on which template may be built
# specify one, not both; leave the other empty (both empty = allow all)
# CAUTION: THE DEFAULTS ONLY APPLY TO NON-FLOWING LAVA AND WATER VARIANTS)
acceptable_target_blocks={Name:"minecraft:grass_block"},{Name:"minecraft:dirt"},{Name:"minecraft:coarse_dirt"},{Name:"minecraft:mycelium"},{Name:"minecraft:podzol"},{Name:"minecraft:stone"},{Name:"minecraft:andesite"},{Name:"minecraft:granite"}
unacceptable_target_blocks=
#
# size of template (#layers, #rows per layer, #blocks per row)
dimensions=23,16,17
#
# max number of missing blocks allowed in surface beneath template
allowable_overhang=0
#
# depth/height limit affected by terrain leveling
# also maximum bumpiness tolerated in surface beneath template
max_leveling=2
#
# padding applied to all sides of template horizontal footprint
# expands area affected by terrain leveling (-1 = no leveling)
leveling_buffer=0
#
# do not rotate template randomly when built (1 = no rotation)
preventRotation=0
#
# treat water/lava blocks as air and protect them from rule0 (1 = yes)
preserve_water=0
preserve_lava=0
#
# minimum distance this template must have from instances of itself
uniqueMinDistance=0
#
# min/max distances this template can be from world spawn (0 = no limit)
# only applies to overworld--i.e., dimension 0
spawnMinDistance=0
spawnMaxDistance=0
#
# other template built nearby whenever this one is
# syntax: <name>;<relativeX>;<maxYdifference>;<relativeZ>[;<chance>]
# may be used more than once to specify multiple neighbors
adjoining_template=

rule1={Properties:{snowy:"false"},Name:"minecraft:grass_block"}
rule2={Properties:{axis:"x"},Name:"minecraft:oak_wood"}
rule3={Name:"minecraft:dirt"}
rule4={Properties:{axis:"y"},Name:"minecraft:oak_wood"}
rule5={Properties:{axis:"z"},Name:"minecraft:oak_wood"}
rule6={Name:"minecraft:coarse_dirt"}
rule7={Properties:{distance:"4",persistent:"true"},Name:"minecraft:oak_leaves"}
rule8={Properties:{distance:"3",persistent:"true"},Name:"minecraft:oak_leaves"}
rule9={Properties:{distance:"2",persistent:"true"},Name:"minecraft:oak_leaves"}
rule10={Properties:{distance:"1",persistent:"true"},Name:"minecraft:oak_leaves"}
rule11={Properties:{distance:"5",persistent:"true"},Name:"minecraft:oak_leaves"}

layer
1,1,1,1,1,1,1,1,1,1,1,1,1,1,1,1,1
1,1,1,1,1,1,1,1,1,1,1,1,1,1,1,1,1
1,1,1,1,1,1,2,1,1,1,1,1,1,1,1,1,1
1,1,1,1,1,3,2,3,3,3,1,1,1,1,1,1,1
1,1,1,1,3,3,3,3,3,3,3,3,1,1,1,1,1
1,1,1,3,3,3,3,3,3,3,3,3,3,1,1,1,1
1,1,1,3,3,3,3,3,3,3,3,3,3,3,1,1,1
1,1,3,3,3,3,3,3,3,3,3,3,3,4,1,1,1
1,1,3,3,3,3,3,3,3,3,3,3,3,1,1,1,1
1,1,1,3,3,3,3,3,3,3,3,3,1,1,1,1,1
1,1,1,3,3,3,3,3,3,3,3,1,1,1,1,1,1
1,1,1,1,1,3,3,3,3,3,3,1,1,1,1,1,1
1,1,1,1,1,3,3,3,3,3,1,1,1,1,1,1,1
1,1,1,1,1,1,1,4,1,1,1,1,1,1,1,1,1
1,1,1,1,1,1,1,1,1,1,1,1,1,1,1,1,1
1,1,1,1,1,1,1,1,1,1,1,1,1,1,1,1,1
endlayer

layer
0,0,0,0,0,0,0,0,0,0,0,0,0,0,0,0,0
0,0,0,0,0,0,0,0,0,0,0,0,0,0,0,0,0
0,0,0,0,0,0,4,0,0,0,0,0,0,0,0,0,0
0,0,0,0,0,1,2,2,1,1,0,0,0,0,0,0,0
0,0,0,0,1,1,2,5,3,1,1,1,0,0,0,0,0
0,0,0,1,1,3,3,3,3,6,1,1,1,0,0,0,0
0,0,0,1,1,3,3,3,3,3,3,3,1,1,0,0,0
0,0,4,5,4,3,3,3,3,3,3,3,3,4,0,0,0
0,0,1,3,3,3,3,4,3,3,3,3,1,0,0,0,0
0,0,0,1,3,3,3,3,3,3,3,1,0,0,0,0,0
0,0,0,1,3,3,3,3,3,3,3,0,0,0,0,0,0
0,0,0,0,0,1,3,3,3,3,1,0,0,0,0,0,0
0,0,0,0,0,1,1,2,1,1,0,0,0,0,0,0,0
0,0,0,0,0,0,0,4,0,0,0,0,0,0,0,0,0
0,0,0,0,0,0,0,0,0,0,0,0,0,0,0,0,0
0,0,0,0,0,0,0,0,0,0,0,0,0,0,0,0,0
endlayer

layer
0,0,0,0,0,0,0,0,0,0,0,0,0,0,0,0,0
0,0,0,0,0,0,0,0,0,0,0,0,0,0,0,0,0
0,0,0,0,0,0,0,0,0,0,0,0,0,0,0,0,0
0,0,0,0,0,0,0,0,0,0,0,0,0,0,0,0,0
0,0,0,0,0,0,1,4,1,0,0,0,0,0,0,0,0
0,0,0,0,0,1,6,4,6,0,0,0,0,0,0,0,0
0,0,0,0,0,6,3,3,3,6,6,1,0,0,0,0,0
0,0,0,4,4,6,6,3,3,5,4,4,4,0,0,0,0
0,0,0,1,1,6,6,4,3,6,1,1,0,0,0,0,0
0,0,0,0,1,1,6,6,6,1,1,0,0,0,0,0,0
0,0,0,0,1,1,1,2,1,1,1,0,0,0,0,0,0
0,0,0,0,0,0,1,2,1,1,0,0,0,0,0,0,0
0,0,0,0,0,0,0,4,0,0,0,0,0,0,0,0,0
0,0,0,0,0,0,0,0,0,0,0,0,0,0,0,0,0
0,0,0,0,0,0,0,0,0,0,0,0,0,0,0,0,0
0,0,0,0,0,0,0,0,0,0,0,0,0,0,0,0,0
endlayer

layer
0,0,0,0,0,0,0,0,0,0,0,0,0,0,0,0,0
0,0,0,0,0,0,0,0,0,0,0,0,0,0,0,0,0
0,0,0,0,0,0,0,0,0,0,0,0,0,0,0,0,0
0,0,0,0,0,0,0,0,0,0,0,0,0,0,0,0,0
0,0,0,0,0,0,0,4,0,0,0,0,0,0,0,0,0
0,0,0,0,0,0,0,4,0,0,0,0,0,0,0,0,0
0,0,0,0,0,0,6,4,4,0,0,0,0,0,0,0,0
0,0,0,0,5,4,0,4,4,4,4,4,0,0,0,0,0
0,0,0,0,0,0,0,4,6,0,0,0,0,0,0,0,0
0,0,0,0,0,0,0,4,0,0,0,0,0,0,0,0,0
0,0,0,0,0,0,0,4,0,0,0,0,0,0,0,0,0
0,0,0,0,0,0,0,4,0,0,0,0,0,0,0,0,0
0,0,0,0,0,0,0,0,0,0,0,0,0,0,0,0,0
0,0,0,0,0,0,0,0,0,0,0,0,0,0,0,0,0
0,0,0,0,0,0,0,0,0,0,0,0,0,0,0,0,0
0,0,0,0,0,0,0,0,0,0,0,0,0,0,0,0,0
endlayer

layer
0,0,0,0,0,0,0,0,0,0,0,0,0,0,0,0,0
0,0,0,0,0,0,0,0,0,0,0,0,0,0,0,0,0
0,0,0,0,0,0,0,0,0,0,0,0,0,0,0,0,0
0,0,0,0,0,0,0,0,0,0,0,0,0,0,0,0,0
0,0,0,0,0,0,0,0,0,0,0,0,0,0,0,0,0
0,0,0,0,0,0,0,0,0,0,0,0,0,0,0,0,0
0,0,0,0,0,0,0,4,4,0,0,0,0,0,0,0,0
0,0,0,0,0,5,5,4,4,5,0,0,0,0,0,0,0
0,0,0,0,0,0,0,2,0,0,0,0,0,0,0,0,0
0,0,0,0,0,0,0,2,0,0,0,0,0,0,0,0,0
0,0,0,0,0,0,0,0,0,0,0,0,0,0,0,0,0
0,0,0,0,0,0,0,0,0,0,0,0,0,0,0,0,0
0,0,0,0,0,0,0,0,0,0,0,0,0,0,0,0,0
0,0,0,0,0,0,0,0,0,0,0,0,0,0,0,0,0
0,0,0,0,0,0,0,0,0,0,0,0,0,0,0,0,0
0,0,0,0,0,0,0,0,0,0,0,0,0,0,0,0,0
endlayer

layer
0,0,0,0,0,0,0,0,0,0,0,0,0,0,0,0,0
0,0,0,0,0,0,0,0,0,0,0,0,0,0,0,0,0
0,0,0,0,0,0,0,0,0,0,0,0,0,0,0,0,0
0,0,0,0,0,0,0,0,0,0,0,0,0,0,0,0,0
0,0,0,0,0,0,0,0,0,0,0,0,0,0,0,0,0
0,0,0,0,0,0,0,0,0,0,0,0,0,0,0,0,0
0,0,0,0,0,0,0,4,4,0,0,0,0,7,0,0,0
0,0,0,0,0,0,0,4,4,0,0,0,0,0,0,0,0
0,0,0,0,0,0,0,0,0,0,0,0,0,0,0,0,0
0,0,0,0,0,0,0,0,0,0,0,0,0,0,0,0,0
0,0,0,0,0,0,0,0,0,0,0,0,0,0,0,0,0
0,0,0,0,0,0,0,0,0,0,0,0,0,0,0,0,0
0,0,0,0,0,0,0,0,0,0,0,0,0,0,0,0,0
0,0,0,0,0,0,0,0,0,0,0,0,0,0,0,0,0
0,0,0,0,0,0,0,0,0,0,0,0,0,0,0,0,0
0,0,0,0,0,0,0,0,0,0,0,0,0,0,0,0,0
endlayer

layer
0,0,0,0,0,0,0,0,0,0,0,0,0,0,0,0,0
0,0,0,0,0,0,0,0,0,0,0,0,0,0,0,0,0
0,0,0,0,0,0,0,0,0,0,0,0,0,0,0,0,0
0,0,0,0,0,0,0,0,0,0,0,0,0,0,0,0,0
0,0,0,0,0,0,0,0,0,0,0,0,0,0,0,0,0
0,0,0,0,0,0,0,0,0,0,0,0,0,0,0,0,0
0,0,0,0,0,0,0,2,4,0,0,0,0,8,0,0,0
0,0,0,0,0,0,0,4,4,0,0,0,0,0,0,0,0
0,0,0,0,0,0,0,0,0,0,0,0,0,0,0,0,0
0,0,0,0,0,0,0,0,0,0,0,0,0,0,0,0,0
0,0,0,0,0,0,0,0,0,0,0,0,0,0,0,0,0
0,0,0,0,0,0,0,0,0,0,0,0,0,0,0,0,0
0,0,0,0,0,0,0,0,0,0,0,0,0,0,0,0,0
0,0,0,0,0,0,0,0,0,0,0,0,0,0,0,0,0
0,0,0,0,0,0,0,0,0,0,0,0,0,0,0,0,0
0,0,0,0,0,0,0,0,0,0,0,0,0,0,0,0,0
endlayer

layer
0,0,0,0,0,0,0,0,0,0,0,0,0,0,0,0,0
0,0,0,0,0,0,0,0,0,0,0,0,0,0,0,0,0
0,0,0,0,0,0,0,0,0,0,0,0,0,0,0,0,0
0,0,0,0,0,0,0,0,0,0,0,0,0,0,0,0,0
0,0,0,0,0,0,0,0,0,0,0,0,0,0,0,0,0
0,0,0,0,0,0,0,0,0,0,0,9,9,8,0,0,0
0,0,0,0,0,0,0,4,4,5,5,10,10,9,0,0,0
0,0,0,0,0,0,0,4,4,0,10,9,9,0,0,0,0
0,0,0,0,0,0,0,0,0,0,0,8,0,0,0,0,0
0,0,0,0,0,0,0,0,0,0,0,0,0,0,0,0,0
0,0,0,0,0,0,0,0,0,0,0,0,0,0,0,0,0
0,0,0,0,0,0,0,0,0,0,0,0,0,0,0,0,0
0,0,0,0,0,0,0,0,0,0,0,0,0,0,0,0,0
0,0,0,0,0,0,0,0,0,0,0,0,0,0,0,0,0
0,0,0,0,0,0,0,0,0,0,0,0,0,0,0,0,0
0,0,0,0,0,0,0,0,0,0,0,0,0,0,0,0,0
endlayer

layer
0,0,0,0,0,0,0,0,0,0,0,0,0,0,0,0,0
0,0,0,0,0,0,0,0,0,0,0,0,0,0,0,0,0
0,0,0,0,0,0,0,0,0,0,0,0,0,0,0,0,0
0,0,0,0,10,0,0,0,0,0,0,0,0,0,0,0,0
0,0,0,10,2,0,0,0,0,0,0,0,9,0,0,0,0
0,0,0,0,5,2,0,0,0,0,0,10,10,9,0,0,0
0,0,0,0,0,5,5,4,0,0,4,5,5,10,9,0,0
0,0,0,0,0,0,0,4,0,0,10,10,10,9,0,0,0
0,0,0,0,0,0,0,0,0,0,9,9,9,0,0,0,0
0,0,0,0,0,0,0,0,0,0,0,0,0,0,0,0,0
0,0,0,0,0,0,0,0,0,0,0,0,0,0,0,0,0
0,0,0,0,0,0,0,0,0,0,0,0,0,0,0,0,0
0,0,0,0,0,0,0,0,0,0,0,0,0,0,0,0,0
0,0,0,0,0,0,0,0,0,0,0,0,0,0,0,0,0
0,0,0,0,0,0,0,0,0,0,0,0,0,0,0,0,0
0,0,0,0,0,0,0,0,0,0,0,0,0,0,0,0,0
endlayer

layer
0,0,0,0,0,0,0,0,0,0,0,0,0,0,0,0,0
0,0,0,0,0,0,0,0,0,0,0,0,0,0,0,0,0
0,0,0,8,9,8,0,0,0,0,0,0,0,0,0,0,0
0,0,8,9,10,9,0,0,0,0,0,0,0,0,0,0,0
0,0,0,10,4,10,0,0,0,0,0,0,0,0,0,0,0
0,0,0,0,0,0,0,0,0,0,0,9,9,8,0,0,0
0,0,0,0,0,0,4,4,0,0,0,10,10,9,0,0,0
0,0,0,0,0,0,4,4,0,0,9,9,9,8,0,0,0
0,0,0,0,0,0,0,0,0,0,8,8,8,0,0,0,0
0,0,0,0,0,9,10,0,0,0,0,0,0,0,0,0,0
0,0,0,0,0,8,9,8,0,0,0,0,0,0,0,0,0
0,0,0,0,0,0,8,0,0,0,0,0,0,0,0,0,0
0,0,0,0,0,0,0,0,0,0,0,0,0,0,0,0,0
0,0,0,0,0,0,0,0,0,0,0,0,0,0,0,0,0
0,0,0,0,0,0,0,0,0,0,0,0,0,0,0,0,0
0,0,0,0,0,0,0,0,0,0,0,0,0,0,0,0,0
endlayer

layer
0,0,0,0,0,0,0,0,0,0,0,0,0,0,0,0,0
0,0,0,11,7,0,0,0,0,0,0,0,0,0,0,0,0
0,0,7,7,8,7,0,0,0,0,0,0,0,0,0,0,0
0,0,8,8,9,8,0,0,0,0,0,0,0,0,0,0,0
0,0,0,9,10,9,0,0,0,0,0,0,0,0,0,0,0
0,0,10,10,9,10,0,0,0,0,7,8,8,0,0,0,0
0,0,0,10,0,5,4,4,0,0,8,9,9,0,0,0,0
0,0,0,0,0,0,4,4,0,0,8,8,8,0,0,0,0
0,0,0,0,0,0,2,0,0,0,0,7,0,0,0,0,0
0,0,0,0,0,10,2,10,0,0,0,0,0,0,0,0,0
0,0,0,0,8,9,10,9,8,0,0,0,0,0,0,0,0
0,0,0,0,0,8,9,8,0,0,0,0,0,0,0,0,0
0,0,0,0,0,0,0,0,0,0,0,0,0,0,0,0,0
0,0,0,0,0,0,0,0,0,0,0,0,0,0,0,0,0
0,0,0,0,0,0,0,0,0,0,0,0,0,0,0,0,0
0,0,0,0,0,0,0,0,0,0,0,0,0,0,0,0,0
endlayer

layer
0,0,0,0,0,0,0,0,0,0,0,0,0,0,0,0,0
0,0,0,7,11,0,0,0,0,0,0,0,0,0,0,0,0
0,0,8,8,7,11,0,9,0,0,0,0,0,0,0,0,0
0,0,9,9,8,7,0,0,0,0,0,0,0,0,0,0,0
0,0,10,10,9,8,0,0,0,0,0,0,0,0,0,0,0
0,10,5,2,10,0,0,2,0,0,0,0,0,0,0,0,0
0,9,10,5,5,5,4,4,0,0,0,8,0,0,0,0,0
0,0,9,10,10,0,4,0,0,0,0,0,7,0,0,0,0
0,0,0,0,0,0,0,0,0,0,0,0,0,0,0,0,0
0,0,0,0,0,0,10,9,0,0,0,0,0,0,0,0,0
0,0,0,0,0,8,9,8,0,0,0,0,0,0,0,0,0
0,0,0,0,0,0,8,7,0,0,0,0,0,0,0,0,0
0,0,0,0,0,0,0,0,0,0,0,0,0,0,0,0,0
0,0,0,0,0,0,0,0,0,0,0,0,0,0,0,0,0
0,0,0,0,0,0,0,0,0,0,0,0,0,0,0,0,0
0,0,0,0,0,0,0,0,0,0,0,0,0,0,0,0,0
endlayer

layer
0,0,0,0,0,0,0,0,0,0,0,0,0,0,0,0,0
0,0,0,0,0,0,0,9,0,0,0,0,0,0,0,0,0
0,0,0,7,0,0,9,10,0,0,0,0,0,0,0,0,0
0,0,0,0,0,0,0,0,0,0,0,0,0,0,0,0,0
0,9,10,9,0,0,0,0,0,0,0,0,0,0,0,0,0
0,10,5,10,9,0,0,2,0,0,0,0,0,0,0,0,0
8,9,10,10,10,0,4,4,0,0,0,0,0,0,0,0,0
0,8,9,9,0,0,4,0,0,0,0,0,0,0,0,0,0
0,0,0,0,0,0,0,0,0,0,0,0,0,0,0,0,0
0,0,0,0,0,0,0,0,0,0,0,0,0,0,0,0,0
0,0,0,0,0,0,8,0,0,0,0,0,0,0,0,0,0
0,0,0,0,0,0,0,0,0,0,0,0,0,0,0,0,0
0,0,0,0,0,0,0,0,0,0,0,0,0,0,0,0,0
0,0,0,0,0,0,0,0,0,0,0,0,0,0,0,0,0
0,0,0,0,0,0,0,0,0,0,0,0,0,0,0,0,0
0,0,0,0,0,0,0,0,0,0,0,0,0,0,0,0,0
endlayer

layer
0,0,0,0,0,0,8,0,0,0,0,0,0,0,0,0,0
0,0,0,0,0,0,9,10,9,0,0,0,0,0,0,0,0
0,0,0,0,0,0,10,4,10,9,0,0,0,0,0,0,0
0,0,0,0,0,0,0,10,9,0,0,0,0,0,0,0,0
0,8,9,8,0,0,0,2,10,0,0,0,0,0,0,0,0
8,9,10,9,8,0,0,4,0,0,0,0,0,0,0,0,0
7,8,9,9,0,0,4,0,0,0,0,0,0,0,0,0,0
0,7,8,0,0,0,0,0,0,0,0,0,0,0,0,0,0
0,0,0,0,0,0,0,0,0,0,0,0,0,0,0,0,0
0,0,0,0,0,0,0,9,8,0,0,0,0,0,0,0,0
0,0,0,0,0,0,0,0,0,0,0,0,0,0,0,0,0
0,0,0,0,0,0,0,0,0,0,0,0,0,0,0,0,0
0,0,0,0,0,0,0,0,0,0,0,0,0,0,0,0,0
0,0,0,0,0,0,0,0,0,0,0,0,0,0,0,0,0
0,0,0,0,0,0,0,0,0,0,0,0,0,0,0,0,0
0,0,0,0,0,0,0,0,0,0,0,0,0,0,0,0,0
endlayer

layer
0,0,0,0,0,0,0,0,0,0,0,0,0,0,0,0,0
0,0,0,0,0,0,9,10,9,0,0,0,0,0,0,0,0
0,0,0,0,0,0,10,2,10,9,0,0,0,0,0,0,0
0,0,0,0,0,0,10,2,10,9,0,0,0,0,0,0,0
0,0,0,0,0,0,10,4,10,9,0,0,0,0,0,0,0
0,8,9,8,0,0,0,0,0,0,0,0,0,0,0,0,0
0,7,8,0,0,0,4,0,0,0,0,0,0,0,0,0,0
0,0,0,0,0,0,0,0,0,0,0,0,0,0,0,0,0
0,0,0,0,0,0,0,9,8,0,0,0,0,0,0,0,0
0,0,0,0,0,9,10,10,9,8,0,0,0,0,0,0,0
0,0,0,0,0,0,9,9,8,0,0,0,0,0,0,0,0
0,0,0,0,0,0,0,0,0,0,0,0,0,0,0,0,0
0,0,0,0,0,0,0,0,0,0,0,0,0,0,0,0,0
0,0,0,0,0,0,0,0,0,0,0,0,0,0,0,0,0
0,0,0,0,0,0,0,0,0,0,0,0,0,0,0,0,0
0,0,0,0,0,0,0,0,0,0,0,0,0,0,0,0,0
endlayer

layer
0,0,0,0,0,0,0,0,0,0,0,0,0,0,0,0,0
0,0,0,0,0,0,0,0,0,0,0,0,0,0,0,0,0
0,0,0,0,0,0,9,10,0,0,0,0,0,0,0,0,0
0,0,0,0,0,0,9,10,9,0,0,0,0,0,0,0,0
0,0,0,0,0,0,9,10,0,0,0,0,0,0,0,0,0
0,0,8,0,0,0,0,0,0,0,0,0,0,0,0,0,0
0,0,0,0,0,0,4,0,0,0,0,0,0,0,0,0,0
0,0,0,0,0,10,2,0,0,0,0,0,0,0,0,0,0
0,0,0,0,0,10,2,10,9,8,0,0,0,0,0,0,0
0,0,0,0,9,10,2,5,10,9,0,0,0,0,0,0,0
0,0,0,0,0,9,10,10,9,0,0,0,0,0,0,0,0
0,0,0,0,0,0,9,0,0,0,0,0,0,0,0,0,0
0,0,0,0,0,0,0,0,0,0,0,0,0,0,0,0,0
0,0,0,0,0,0,0,0,0,0,0,0,0,0,0,0,0
0,0,0,0,0,0,0,0,0,0,0,0,0,0,0,0,0
0,0,0,0,0,0,0,0,0,0,0,0,0,0,0,0,0
endlayer

layer
0,0,0,0,0,0,0,0,0,0,0,0,0,0,0,0,0
0,0,0,0,0,0,0,0,0,0,0,0,0,0,0,0,0
0,0,0,0,0,0,0,0,0,0,0,0,0,0,0,0,0
0,0,0,0,0,0,0,0,0,0,0,0,0,0,0,0,0
0,0,0,0,0,0,0,0,0,0,0,0,0,0,0,0,0
0,0,0,0,0,0,0,0,0,0,0,0,0,0,0,0,0
0,0,0,0,5,5,4,0,0,0,0,0,0,0,0,0,0
0,0,0,0,0,0,4,0,0,0,0,0,0,0,0,0,0
0,0,0,0,0,0,10,9,0,0,0,0,0,0,0,0,0
0,0,0,0,0,9,10,10,9,0,0,0,0,0,0,0,0
0,0,0,0,0,0,9,9,0,0,0,0,0,0,0,0,0
0,0,0,0,0,0,0,0,0,0,0,0,0,0,0,0,0
0,0,0,0,0,0,0,0,0,0,0,0,0,0,0,0,0
0,0,0,0,0,0,0,0,0,0,0,0,0,0,0,0,0
0,0,0,0,0,0,0,0,0,0,0,0,0,0,0,0,0
0,0,0,0,0,0,0,0,0,0,0,0,0,0,0,0,0
endlayer

layer
0,0,0,0,0,0,0,0,0,0,0,0,0,0,0,0,0
0,0,0,0,0,0,0,0,0,0,0,0,0,0,0,0,0
0,0,0,0,0,0,0,0,0,0,0,0,0,0,0,0,0
0,0,0,0,0,0,0,0,0,0,0,0,0,0,0,0,0
0,0,0,0,0,0,0,0,0,0,0,0,0,0,0,0,0
0,0,0,9,10,0,0,0,0,0,0,0,0,0,0,0,0
0,0,9,10,4,0,0,0,0,0,0,0,0,0,0,0,0
0,0,0,9,10,0,4,0,0,0,0,0,0,0,0,0,0
0,0,0,0,0,0,0,0,0,0,0,0,0,0,0,0,0
0,0,0,0,0,0,0,9,0,0,0,0,0,0,0,0,0
0,0,0,0,0,0,0,0,0,0,0,0,0,0,0,0,0
0,0,0,0,0,0,0,0,0,0,0,0,0,0,0,0,0
0,0,0,0,0,0,0,0,0,0,0,0,0,0,0,0,0
0,0,0,0,0,0,0,0,0,0,0,0,0,0,0,0,0
0,0,0,0,0,0,0,0,0,0,0,0,0,0,0,0,0
0,0,0,0,0,0,0,0,0,0,0,0,0,0,0,0,0
endlayer

layer
0,0,0,0,0,0,0,0,0,0,0,0,0,0,0,0,0
0,0,0,0,0,0,0,0,0,0,0,0,0,0,0,0,0
0,0,0,0,0,0,0,0,0,0,0,0,0,0,0,0,0
0,0,0,0,0,0,0,0,0,0,0,0,0,0,0,0,0
0,0,0,7,8,0,0,0,0,0,0,0,0,0,0,0,0
0,0,7,8,9,9,9,8,0,0,0,0,0,0,0,0,0
0,7,8,9,10,10,10,9,0,0,0,0,0,0,0,0,0
0,0,7,8,9,10,4,10,0,0,0,0,0,0,0,0,0
0,0,0,0,0,10,2,10,0,0,0,0,0,0,0,0,0
0,0,0,0,0,0,10,0,0,0,0,0,0,0,0,0,0
0,0,0,0,0,0,0,0,0,0,0,0,0,0,0,0,0
0,0,0,0,0,0,0,0,0,0,0,0,0,0,0,0,0
0,0,0,0,0,0,0,0,0,0,0,0,0,0,0,0,0
0,0,0,0,0,0,0,0,0,0,0,0,0,0,0,0,0
0,0,0,0,0,0,0,0,0,0,0,0,0,0,0,0,0
0,0,0,0,0,0,0,0,0,0,0,0,0,0,0,0,0
endlayer

layer
0,0,0,0,0,0,0,0,0,0,0,0,0,0,0,0,0
0,0,0,0,0,0,0,0,0,0,0,0,0,0,0,0,0
0,0,0,0,0,0,0,0,0,0,0,0,0,0,0,0,0
0,0,0,0,0,0,0,0,0,0,0,0,0,0,0,0,0
0,0,0,0,8,0,0,8,0,0,0,0,0,0,0,0,0
0,0,0,8,9,10,10,9,8,0,0,0,0,0,0,0,0
0,0,8,9,10,5,4,10,0,0,0,0,0,0,0,0,0
0,0,0,8,9,10,10,9,0,0,0,0,0,0,0,0,0
0,0,0,0,9,10,4,10,9,0,0,0,0,0,0,0,0
0,0,0,0,0,9,10,9,0,0,0,0,0,0,0,0,0
0,0,0,0,0,0,9,8,0,0,0,0,0,0,0,0,0
0,0,0,0,0,0,0,0,0,0,0,0,0,0,0,0,0
0,0,0,0,0,0,0,0,0,0,0,0,0,0,0,0,0
0,0,0,0,0,0,0,0,0,0,0,0,0,0,0,0,0
0,0,0,0,0,0,0,0,0,0,0,0,0,0,0,0,0
0,0,0,0,0,0,0,0,0,0,0,0,0,0,0,0,0
endlayer

layer
0,0,0,0,0,0,0,0,0,0,0,0,0,0,0,0,0
0,0,0,0,0,0,0,0,0,0,0,0,0,0,0,0,0
0,0,0,0,0,0,0,0,0,0,0,0,0,0,0,0,0
0,0,0,0,0,0,0,0,0,0,0,0,0,0,0,0,0
0,0,0,0,0,0,8,7,0,0,0,0,0,0,0,0,0
0,0,0,8,9,10,9,8,0,0,0,0,0,0,0,0,0
0,0,0,9,10,4,10,9,0,0,0,0,0,0,0,0,0
0,0,0,8,9,10,0,8,0,0,0,0,0,0,0,0,0
0,0,0,0,8,9,10,9,0,0,0,0,0,0,0,0,0
0,0,0,0,7,8,9,8,0,0,0,0,0,0,0,0,0
0,0,0,0,0,7,8,7,0,0,0,0,0,0,0,0,0
0,0,0,0,0,0,0,0,0,0,0,0,0,0,0,0,0
0,0,0,0,0,0,0,0,0,0,0,0,0,0,0,0,0
0,0,0,0,0,0,0,0,0,0,0,0,0,0,0,0,0
0,0,0,0,0,0,0,0,0,0,0,0,0,0,0,0,0
0,0,0,0,0,0,0,0,0,0,0,0,0,0,0,0,0
endlayer

layer
0,0,0,0,0,0,0,0,0,0,0,0,0,0,0,0,0
0,0,0,0,0,0,0,0,0,0,0,0,0,0,0,0,0
0,0,0,0,0,0,0,0,0,0,0,0,0,0,0,0,0
0,0,0,0,0,0,0,0,0,0,0,0,0,0,0,0,0
0,0,0,0,0,0,7,0,0,0,0,0,0,0,0,0,0
0,0,0,0,8,9,8,7,0,0,0,0,0,0,0,0,0
0,0,0,0,9,10,9,0,0,0,0,0,0,0,0,0,0
0,0,0,0,8,9,0,0,0,0,0,0,0,0,0,0,0
0,0,0,0,0,0,0,8,0,0,0,0,0,0,0,0,0
0,0,0,0,0,7,8,7,0,0,0,0,0,0,0,0,0
0,0,0,0,0,0,7,0,0,0,0,0,0,0,0,0,0
0,0,0,0,0,0,0,0,0,0,0,0,0,0,0,0,0
0,0,0,0,0,0,0,0,0,0,0,0,0,0,0,0,0
0,0,0,0,0,0,0,0,0,0,0,0,0,0,0,0,0
0,0,0,0,0,0,0,0,0,0,0,0,0,0,0,0,0
0,0,0,0,0,0,0,0,0,0,0,0,0,0,0,0,0
endlayer

layer
0,0,0,0,0,0,0,0,0,0,0,0,0,0,0,0,0
0,0,0,0,0,0,0,0,0,0,0,0,0,0,0,0,0
0,0,0,0,0,0,0,0,0,0,0,0,0,0,0,0,0
0,0,0,0,0,0,0,0,0,0,0,0,0,0,0,0,0
0,0,0,0,0,0,0,0,0,0,0,0,0,0,0,0,0
0,0,0,0,0,0,0,0,0,0,0,0,0,0,0,0,0
0,0,0,0,0,9,0,0,0,0,0,0,0,0,0,0,0
0,0,0,0,0,0,0,0,0,0,0,0,0,0,0,0,0
0,0,0,0,0,0,0,0,0,0,0,0,0,0,0,0,0
0,0,0,0,0,0,7,0,0,0,0,0,0,0,0,0,0
0,0,0,0,0,0,0,0,0,0,0,0,0,0,0,0,0
0,0,0,0,0,0,0,0,0,0,0,0,0,0,0,0,0
0,0,0,0,0,0,0,0,0,0,0,0,0,0,0,0,0
0,0,0,0,0,0,0,0,0,0,0,0,0,0,0,0,0
0,0,0,0,0,0,0,0,0,0,0,0,0,0,0,0,0
0,0,0,0,0,0,0,0,0,0,0,0,0,0,0,0,0
endlayer

