
# Created by Ruins mod Ingame Parser
# authoring Player: Syndaryl

# TEMPLATE PARAMETER SETTINGS:
#
# criterion expression specifying mod ids required to load template
# may include plus (AND), minus (AND NOT), comma (OR), and parentheses
# all required mods listed must be present; no prohibited mods can be
requiredMods=
#
# likelihood this template will be chosen relative to all others
# e.g., a weight=6 template is chosen 3X as often as one with weight=2
weight=1
#
# list of dimensions in which this template may spawn, even if generic
# one or more dimension names, separated by commas (blank = all)
dimensionsToSpawnIn=
#
# list of other biomes in which this template may spawn
# biome corresponding to directory is always assumed, listed or not
# generic templates should leave this list empty
biomesToSpawnIn=
#
# criterion expression specifying types of biome where template spawns
# this is in addition to those explicitly listed as biomesToSpawnIn
# generic templates should leave this list empty
biomeTypesToSpawnIn=FOREST,PLAINS,HILLS,MOUNTAIN
#
# list of biomes in which this template may not spawn
# takes precedence over biomeTypesToSpawnIn, but NOT biomesToSpawnIn
# should be empty if biomeTypesToSpawnIn is empty
biomesToNotSpawnIn=
#
# depth template is pushed down into the surface when built
# offset is min/max range of random additional bury depth
embed_into_distance=6
random_height_offset=0,0
#
# whitelist/blacklist of block states on which template may be built
# specify one, not both; leave the other empty (both empty = allow all)
# CAUTION: THE DEFAULTS ONLY APPLY TO NON-FLOWING LAVA AND WATER VARIANTS)
acceptable_target_blocks={Name:"minecraft:grass_block"},{Name:"minecraft:dirt"},{Name:"minecraft:coarse_dirt"},{Name:"minecraft:mycelium"},{Name:"minecraft:podzol"},{Name:"minecraft:stone"},{Name:"minecraft:andesite"},{Name:"minecraft:granite"}
unacceptable_target_blocks=
#
# size of template (#layers, #rows per layer, #blocks per row)
dimensions=17,21,26
#
# max number of missing blocks allowed in surface beneath template
allowable_overhang=0
#
# depth/height limit affected by terrain leveling
# also maximum bumpiness tolerated in surface beneath template
max_leveling=2
#
# padding applied to all sides of template horizontal footprint
# expands area affected by terrain leveling (-1 = no leveling)
leveling_buffer=0
#
# do not rotate template randomly when built (1 = no rotation)
preventRotation=0
#
# treat water/lava blocks as air and protect them from rule0 (1 = yes)
preserve_water=0
preserve_lava=0
#
# minimum distance this template must have from instances of itself
uniqueMinDistance=0
#
# min/max distances this template can be from world spawn (0 = no limit)
# only applies to overworld--i.e., dimension 0
spawnMinDistance=0
spawnMaxDistance=0
#
# other template built nearby whenever this one is
# syntax: <name>;<relativeX>;<maxYdifference>;<relativeZ>[;<chance>]
# may be used more than once to specify multiple neighbors
adjoining_template=

rule1={Name:"minecraft:stone",Ruins:{weight:3}},{Name:"minecraft:andesite"}
rule2={Name:"minecraft:stone",Ruins:{weight:8}},{Name:"minecraft:coal_ore",Ruins:{weight:12}},{Name:"minecraft:iron_ore",Ruins:{weight:3}},{Name:"minecraft:gold_ore",Ruins:{weight:1}}
rule3={Name:"minecraft:oak_fence"}
rule4={Properties:{shape:"east_west"},Name:"minecraft:rail"}
rule5={Properties:{half:"bottom",waterlogged:"false",shape:"straight",facing:"north"},Name:"minecraft:stone_stairs"}
rule6={Properties:{shape:"ascending_east"},Name:"minecraft:rail"}
rule7={Properties:{half:"bottom",waterlogged:"false",shape:"straight",facing:"south"},Name:"minecraft:stone_stairs"}
rule8={Properties:{half:"bottom",waterlogged:"false",shape:"straight",facing:"east"},Name:"minecraft:stone_brick_stairs"}
rule9={Name:"air"}
rule10={Name:"air"}
rule11={Name:"minecraft:dirt"}
rule12={Name:"minecraft:chiseled_stone_bricks"}
rule13={Name:"minecraft:oak_fence"}
rule14={Name:"minecraft:oak_fence"}
rule15={Name:"minecraft:oak_fence"}
rule16={Name:"minecraft:stone_bricks",Ruins:{weight:3}},{Name:"minecraft:cracked_stone_bricks"}
rule17={Properties:{half:"top",waterlogged:"false",shape:"inner_right",facing:"west"},Name:"minecraft:stone_stairs"}
rule18={Properties:{half:"top",waterlogged:"false",shape:"straight",facing:"west"},Name:"minecraft:stone_stairs"}
rule19={Properties:{half:"top",waterlogged:"false",shape:"inner_left",facing:"west"},Name:"minecraft:stone_stairs"}
rule20={Properties:{half:"top",waterlogged:"false",shape:"straight",facing:"south"},Name:"minecraft:stone_stairs"}
rule21={Ruins:{entity:{ForgeData:{LootTable:"minecraft:chests/simple_dungeon"},Items:[]}},Properties:{waterlogged:"false",facing:"north",type:"single"},Name:"minecraft:chest"}
rule22={Properties:{half:"bottom",waterlogged:"false",shape:"straight",facing:"east"},Name:"minecraft:stone_stairs"}
rule23={Properties:{shape:"south_west"},Name:"minecraft:rail"}
rule24={Properties:{shape:"north_south"},Name:"minecraft:rail"}
rule25={Properties:{shape:"ascending_south"},Name:"minecraft:rail"}
rule26={Properties:{half:"bottom",waterlogged:"false",shape:"straight",facing:"south"},Name:"minecraft:stone_brick_stairs"}
rule27={Properties:{half:"bottom",waterlogged:"false",shape:"inner_right",facing:"east"},Name:"minecraft:stone_stairs"}
rule28={Properties:{snowy:"false"},Name:"minecraft:grass_block",Ruins:{weight:1,bonemeal:1}},{Properties:{snowy:"false"},Name:"minecraft:grass_block",Ruins:{weight:15}}
rule29={Properties:{half:"top",waterlogged:"false",shape:"inner_right",facing:"south"},Name:"minecraft:stone_stairs"}
rule30={Name:"air"}
rule31={Properties:{hanging:"true"},Name:"minecraft:lantern"}
rule32={Properties:{waterlogged:"false",type:"top"},Name:"minecraft:stone_slab"}
rule33={Properties:{waterlogged:"false",type:"top"},Name:"minecraft:iron_bars"}
rule34={Properties:{half:"top",waterlogged:"false",shape:"outer_right",facing:"north"},Name:"minecraft:stone_stairs"}
rule35={Name:"minecraft:gravel"}
rule36={Properties:{half:"top",waterlogged:"false",shape:"inner_right",facing:"north"},Name:"minecraft:stone_stairs"}
rule37={Properties:{half:"top",waterlogged:"false",shape:"straight",facing:"east"},Name:"minecraft:stone_stairs"}
rule38={Properties:{half:"bottom",waterlogged:"false",shape:"straight",facing:"west"},Name:"minecraft:stone_stairs"}
rule39={Properties:{half:"top",waterlogged:"false",shape:"straight",facing:"north"},Name:"minecraft:stone_stairs"}
rule40={Name:"minecraft:stone",Ruins:{weight:3}},{Name:"minecraft:andesite"},{Name:"air",Ruins:{weight:5}}
rule41={Name:"air"}
rule42={Name:"minecraft:oak_fence"}
rule43={Name:"minecraft:oak_fence"}
rule44={Properties:{shape:"north_east"},Name:"minecraft:rail"}
rule45={Name:"minecraft:oak_fence"}
rule46={Properties:{powered:"false",shape:"east_west"},Name:"minecraft:powered_rail"}
rule47={Ruins:{entity:{Items:[{Slot:3b,id:"minecraft:rail",Count:5b},{Slot:7b,id:"minecraft:redstone_torch",Count:1b},{Slot:10b,id:"minecraft:chest_minecart",Count:1b},{Slot:14b,id:"minecraft:iron_bars",Count:2b},{Slot:20b,id:"minecraft:minecart",Count:1b},{Slot:25b,id:"minecraft:rail",Count:6b}]}},Properties:{waterlogged:"false",facing:"south",type:"single"},Name:"minecraft:chest"}
rule48={Properties:{half:"bottom",waterlogged:"false",shape:"straight",facing:"west"},Name:"minecraft:spruce_stairs"}
rule49={Properties:{half:"top",waterlogged:"false",shape:"outer_left",facing:"west"},Name:"minecraft:stone_stairs"}
rule50={Properties:{waterlogged:"false",type:"bottom"},Name:"minecraft:stone_slab"}
rule51={Properties:{half:"top",waterlogged:"false",shape:"outer_left",facing:"north"},Name:"minecraft:stone_stairs"}
rule52={Name:"minecraft:oak_fence"}
rule53={Name:"minecraft:oak_fence"}
#rule54={Properties:{facing:"east"},Name:"mcwroofs:oak_roof_outer"}
#rule55={Properties:{facing:"north"},Name:"mcwroofs:oak_roof_straight"}
#rule56={Properties:{facing:"east"},Name:"mcwroofs:oak_roof_straight"}
#rule57={Properties:{facing:"east"},Name:"mcwroofs:oak_roof_lower"}
#rule58={Properties:{facing:"west"},Name:"mcwroofs:oak_roof_outer"}
#rule59={Properties:{facing:"north"},Name:"mcwroofs:oak_roof_lower"}
#rule60={Properties:{facing:"north"},Name:"mcwroofs:oak_roof_outer"}
rule54={Name:"minecraft:spruce_planks"}
rule55={Properties:{type:"bottom",waterlogged:"false"},Name:"minecraft:spruce_slab"}
rule56={Properties:{type:"top",waterlogged:"false"},Name:"minecraft:spruce_slab"}
rule57={Name:"air"}
rule58={Name:"air",Ruins:{weight:3}},{Properties:{stage:"0"},Name:"minecraft:spruce_sapling",Ruins:{weight:1,bonemeal:5}},{Properties:{stage:"0"},Name:"minecraft:birch_sapling",Ruins:{weight:1,bonemeal:5}},{Properties:{stage:"0"},Name:"minecraft:oak_sapling",Ruins:{weight:1,bonemeal:5}}
rule59={Properties:{half:"bottom",waterlogged:"false",shape:"outer_right",facing:"west"},Name:"minecraft:spruce_stairs"}
rule60={Properties:{half:"top",waterlogged:"false",shape:"inner_right",facing:"east"},Name:"minecraft:stone_stairs"}
rule62={Properties:{half:"bottom",waterlogged:"false",shape:"outer_right",facing:"east"},Name:"minecraft:stone_stairs"}
rule63={Properties:{half:"bottom",waterlogged:"false",shape:"outer_left",facing:"west"},Name:"minecraft:stone_stairs"}


layer
1,1,1,1,1,1,1,1,1,1,1,1,1,1,1,1,1,1,1,1,1,1,1,1,1,1
1,1,1,1,1,1,1,1,1,1,1,1,1,1,1,1,1,1,1,1,1,1,1,1,1,1
1,1,1,1,1,1,1,1,1,1,1,1,1,1,1,1,1,2,2,1,1,1,1,1,1,1
1,1,1,1,1,1,1,1,1,1,1,1,1,1,1,1,1,2,2,1,1,1,1,1,1,1
1,1,1,1,1,1,1,1,1,1,1,1,1,1,1,1,1,2,57,2,1,1,1,1,1,1
1,1,1,1,1,1,1,1,1,1,1,1,1,1,1,1,3,57,4,57,3,1,1,1,1,1
1,1,1,1,1,1,1,1,1,1,1,1,1,1,1,1,7,57,6,57,5,1,1,1,1,1
1,1,1,1,1,1,1,1,1,1,1,1,1,1,1,1,1,1,1,8,1,1,1,1,1,1
1,1,1,1,1,1,1,1,1,1,1,1,1,1,1,1,1,1,1,1,1,1,1,1,1,1
1,1,1,1,1,1,1,1,1,1,1,1,1,1,1,1,1,1,1,1,1,1,1,1,1,1
1,1,1,1,1,1,1,1,1,1,1,1,1,1,1,1,1,1,1,1,1,1,1,1,1,1
1,1,1,1,1,1,1,1,1,1,1,1,1,1,1,1,1,1,1,1,1,1,1,1,1,1
1,1,1,1,1,1,1,1,1,1,1,1,1,1,1,1,1,1,1,1,1,1,1,1,1,1
1,1,1,1,1,1,1,1,1,1,1,1,1,1,1,1,1,1,1,1,1,1,1,1,1,1
1,1,1,1,1,1,1,1,1,1,1,1,1,1,1,1,1,1,1,1,1,1,1,1,1,1
1,1,1,1,1,1,1,1,1,1,1,1,1,1,1,1,1,1,1,1,1,1,1,1,1,1
1,1,1,1,1,1,1,1,1,1,1,1,1,1,1,1,1,1,1,1,1,1,1,1,1,1
1,1,1,1,1,1,1,1,1,1,1,1,1,1,1,1,1,1,1,1,1,1,1,1,1,1
1,1,1,1,1,1,1,1,1,1,1,1,1,1,1,1,1,1,1,1,1,1,1,1,1,1
1,1,1,1,1,1,1,1,1,1,1,1,1,1,1,1,1,1,1,1,1,1,1,1,1,1
1,1,1,1,1,1,1,1,1,1,1,1,1,1,1,1,1,1,1,1,1,1,1,1,1,1
endlayer

layer
1,1,1,1,1,1,1,1,1,1,1,1,1,1,1,1,1,1,1,1,1,1,1,1,1,1
1,1,1,1,1,1,1,1,1,1,1,1,1,1,1,1,1,1,1,1,1,1,1,1,1,1
1,1,1,1,1,1,1,1,1,1,1,1,1,1,1,1,1,1,2,1,1,1,1,1,1,1
1,1,1,1,1,1,1,1,1,1,1,1,1,1,1,1,1,2,2,1,1,1,1,1,1,1
1,1,1,1,1,1,1,1,1,1,1,1,1,1,1,1,1,2,2,2,1,1,1,1,1,1
1,1,1,1,1,1,1,1,1,1,1,1,1,1,1,1,3,57,57,57,3,1,1,1,1,1
1,1,1,1,1,1,1,1,1,1,1,1,1,1,1,1,10,57,57,57,9,1,1,1,1,1
1,1,1,1,1,1,1,1,1,1,1,1,1,1,1,1,10,57,6,57,1,1,1,1,1,1
1,1,1,1,1,1,1,1,1,1,1,1,1,1,1,1,1,1,1,8,1,1,1,1,1,1
1,1,1,1,1,1,1,1,1,1,1,1,1,1,1,1,1,1,1,1,1,1,1,1,1,1
1,1,1,1,1,1,1,1,1,1,1,1,1,1,1,1,1,1,1,1,1,1,1,1,1,1
1,1,1,1,1,1,1,1,1,1,1,1,1,1,1,1,1,1,1,1,1,1,1,1,1,1
1,1,1,1,1,1,1,1,1,1,1,1,1,1,1,1,1,1,1,1,1,1,1,1,1,1
1,1,1,1,1,1,1,1,1,1,1,1,1,1,1,1,1,1,1,1,1,1,1,1,1,1
1,1,1,1,1,1,1,1,1,1,1,1,1,1,1,1,1,1,1,1,1,1,1,1,1,1
1,1,1,1,1,1,1,1,1,1,1,1,1,1,1,1,1,1,1,1,1,1,1,1,1,1
1,1,1,1,1,1,1,1,1,1,1,1,1,1,1,1,1,1,1,1,1,1,1,1,1,1
1,1,1,1,1,1,1,1,1,1,1,1,1,1,1,1,1,1,1,1,1,1,1,1,1,1
1,1,1,1,1,1,1,1,1,1,1,1,1,1,1,1,1,1,1,1,1,1,1,1,1,1
1,1,1,1,1,1,1,1,1,1,1,1,1,1,1,1,1,1,1,1,1,1,1,1,1,1
1,1,1,1,1,1,1,1,1,1,1,1,1,1,1,1,1,1,1,1,1,1,1,1,1,1
endlayer

layer
11,1,1,1,1,1,1,1,1,1,1,1,1,1,1,1,1,1,1,1,1,1,1,1,1,1
11,1,1,1,1,1,1,1,1,1,1,1,1,1,1,1,1,1,1,1,1,1,1,1,1,1
11,1,1,1,1,1,1,1,1,1,1,1,1,1,1,1,1,1,1,1,1,1,1,1,1,1
11,1,1,1,1,1,1,1,1,1,1,1,1,1,1,1,1,1,1,1,1,1,1,1,1,1
1,1,1,1,1,1,1,1,1,1,1,1,1,1,1,1,1,2,1,1,1,1,1,1,1,1
1,1,1,1,1,1,1,1,1,1,1,1,1,1,1,1,3,57,57,57,3,1,1,1,1,1
1,1,1,1,1,1,1,1,1,1,1,1,1,1,1,1,57,57,57,57,57,1,1,1,1,1
1,1,1,1,1,1,1,1,1,1,1,1,1,1,1,1,10,57,57,57,1,1,1,1,1,1
1,1,1,1,1,1,1,1,1,1,1,1,1,1,1,7,57,57,6,57,1,1,1,1,1,1
1,1,1,1,1,1,1,1,1,1,1,1,1,1,1,1,1,1,1,8,12,1,1,1,1,1
1,1,1,1,1,1,1,1,1,1,1,1,1,1,1,1,1,1,1,1,1,1,1,1,1,1
1,1,1,1,1,1,1,1,1,1,1,1,1,1,1,1,1,1,1,1,1,1,1,1,1,1
1,1,1,1,1,1,1,1,1,1,1,1,1,1,1,1,1,1,1,1,1,1,1,1,1,1
1,1,1,1,1,1,1,1,1,1,1,1,1,1,1,1,1,1,1,1,1,1,1,1,1,1
1,1,1,1,1,1,1,1,1,1,1,1,1,1,1,1,1,1,1,1,1,1,1,1,1,1
1,1,1,1,1,1,1,1,1,1,1,1,1,1,1,1,1,1,1,1,1,1,1,1,1,1
1,1,1,1,1,1,1,1,1,1,1,1,1,1,1,1,1,1,1,1,1,1,1,1,1,1
1,1,1,1,1,1,1,1,1,1,1,1,1,1,1,1,1,1,1,1,1,1,11,11,1,1
1,1,1,1,1,1,1,1,1,1,1,1,1,1,1,1,1,1,1,1,1,1,11,11,1,1
1,1,1,1,1,1,1,1,1,1,1,1,1,1,1,1,1,1,1,1,1,1,1,1,1,1
11,11,11,1,1,1,1,1,1,1,1,1,1,1,1,1,1,1,1,1,1,1,1,1,1,1
endlayer

layer
11,11,11,11,11,11,1,1,1,1,1,1,1,1,1,1,1,1,1,1,1,1,1,11,11,11
11,11,11,11,11,11,1,1,1,1,1,1,1,1,1,1,1,1,1,1,1,1,1,11,11,11
11,11,11,11,11,11,1,1,1,1,1,1,1,1,1,1,1,1,1,1,1,1,1,11,11,11
11,11,11,11,11,11,1,1,1,1,1,1,1,1,1,1,1,1,1,1,1,1,1,11,11,11
11,11,11,11,11,1,1,1,1,1,1,1,1,1,1,1,1,1,1,1,1,1,1,1,11,11
11,11,11,1,1,1,1,1,1,1,1,1,1,1,1,1,15,14,14,14,13,1,1,1,1,11
11,11,1,1,1,1,1,1,1,1,1,1,1,1,1,1,10,57,57,57,9,1,1,1,1,1
11,11,1,1,1,1,1,1,1,1,1,1,1,1,1,1,10,57,57,57,1,1,1,1,1,1
11,11,1,1,1,1,1,1,1,1,1,1,1,1,1,10,57,57,57,57,1,1,1,1,1,1
11,11,1,1,1,1,1,1,1,1,1,1,1,1,1,7,12,57,6,57,12,1,1,1,1,1
11,11,11,1,1,1,1,1,1,1,1,1,1,2,1,1,1,1,1,8,1,1,1,1,1,1
11,11,11,1,1,1,1,1,1,1,1,1,1,1,1,1,1,1,1,16,1,1,1,1,1,1
11,11,1,1,1,1,1,1,1,1,1,1,1,1,1,1,16,16,16,16,1,1,1,1,1,1
11,1,1,1,1,1,1,1,1,1,1,1,1,1,1,1,1,1,1,1,1,1,1,1,1,1
11,1,1,1,1,1,1,1,1,1,1,1,1,1,1,1,1,1,1,1,1,1,1,1,1,1
11,1,1,1,1,1,1,1,1,1,1,1,1,1,1,1,1,1,1,1,1,1,1,1,1,11
11,11,1,1,1,1,1,1,1,1,1,1,1,1,1,1,1,1,1,1,1,1,1,1,1,11
11,11,1,1,1,1,1,1,1,1,1,1,1,1,1,1,1,1,1,1,1,1,11,11,1,11
11,11,11,1,1,1,1,1,1,1,1,1,1,1,1,1,1,1,1,1,1,1,11,11,1,11
11,11,11,11,1,1,1,1,1,1,1,1,1,1,1,1,1,1,1,1,1,1,1,1,11,11
11,11,11,11,11,11,1,1,1,1,1,1,11,11,11,1,1,1,1,1,1,11,11,11,11,11
endlayer

layer
11,11,11,11,11,11,11,11,11,1,1,1,1,1,1,1,1,1,1,1,1,1,1,11,11,11
11,11,11,11,11,11,11,11,11,1,1,1,1,1,1,1,1,1,1,1,1,1,1,11,11,11
11,11,11,11,11,11,11,11,11,1,1,1,1,1,1,1,1,1,1,1,1,1,1,11,11,11
11,11,11,11,11,11,11,11,11,1,1,1,1,1,1,1,1,1,1,1,1,1,1,11,11,11
11,11,11,11,11,11,11,1,1,1,1,1,1,1,1,1,1,1,1,1,1,1,1,11,11,11
11,11,11,11,11,11,1,1,1,1,1,1,1,1,1,1,1,1,1,1,1,1,1,11,11,11
11,11,11,1,1,1,1,1,1,1,1,1,1,1,1,1,1,19,18,17,1,1,1,1,11,11
11,11,11,1,1,1,1,1,1,1,1,1,1,1,1,1,10,57,57,57,1,1,1,1,1,11
11,11,11,1,1,1,1,1,1,1,1,1,1,1,1,20,57,57,57,57,1,1,1,1,1,11
11,11,11,1,1,1,1,1,1,1,1,1,1,1,1,57,3,57,57,57,3,1,1,1,1,1
11,11,11,11,1,1,1,1,1,1,1,1,2,2,1,22,21,57,4,57,1,1,1,1,1,1
11,11,11,11,1,1,1,1,1,1,1,1,2,2,1,1,25,24,23,57,1,1,1,1,1,1
11,11,11,1,1,1,1,1,1,1,1,1,1,1,1,26,57,57,57,57,1,1,1,1,1,1
11,11,1,1,1,1,1,1,1,1,1,1,1,1,1,27,2,2,2,1,1,1,1,1,1,1
11,11,1,1,1,1,1,1,1,1,1,1,1,1,1,1,2,2,2,1,1,1,1,1,11,11
11,11,11,1,1,1,1,1,1,1,1,1,1,1,1,1,1,1,1,1,1,1,1,11,11,11
11,11,11,1,1,1,1,1,1,1,1,1,1,1,1,1,1,1,1,1,1,1,11,11,11,11
11,11,11,11,1,1,1,1,1,1,1,1,1,1,1,1,1,1,1,1,1,1,11,11,11,11
11,11,11,11,1,1,1,1,1,1,1,1,1,1,1,1,1,1,1,1,1,11,11,11,11,11
11,11,11,11,11,11,11,1,1,1,1,1,1,1,1,1,1,1,1,1,1,11,11,11,11,11
11,11,11,11,11,11,11,11,11,11,11,11,11,11,11,1,11,11,11,11,11,11,11,11,11,11
endlayer

layer
28,28,28,28,28,11,11,11,11,11,11,11,11,1,1,1,1,1,1,1,1,1,28,28,28,28
28,28,28,11,11,11,11,11,11,11,11,11,11,1,1,1,1,1,1,1,1,1,11,11,11,28
28,28,11,11,11,11,11,11,11,11,11,11,11,1,1,1,1,1,1,1,1,1,11,11,11,28
28,28,11,11,11,11,11,11,11,11,11,11,11,1,1,1,1,1,1,1,1,1,11,11,11,11
28,11,11,11,11,11,11,11,11,1,1,1,1,1,1,1,1,1,1,1,1,1,11,11,11,11
28,11,11,11,11,11,11,11,1,1,1,1,1,1,1,1,1,1,1,1,1,1,11,11,11,11
28,11,11,11,11,11,1,1,1,1,1,1,1,1,1,1,1,1,1,1,1,1,1,11,11,11
28,11,11,11,11,1,1,1,1,1,1,1,1,1,1,1,29,18,18,18,1,1,1,11,11,11
28,11,11,11,11,1,1,1,1,1,1,1,1,1,1,1,20,57,57,57,1,1,1,1,11,11
11,11,11,11,11,1,1,1,1,1,1,1,1,1,1,57,3,57,57,57,3,1,1,1,11,11
11,11,11,11,11,11,11,1,1,1,1,1,1,1,7,57,57,57,57,57,1,11,11,1,1,1
11,11,11,11,11,11,11,11,1,1,1,1,2,1,1,25,57,57,57,57,1,1,1,1,1,1
11,11,11,11,11,11,11,1,1,1,1,1,1,1,26,57,57,57,57,57,1,1,1,1,1,1
11,11,11,11,11,11,11,1,1,1,1,1,1,1,12,30,2,2,2,1,1,1,1,1,1,11
11,11,11,11,11,11,11,11,1,1,1,1,1,1,1,1,2,2,2,1,1,1,1,1,11,11
11,11,11,11,11,11,11,1,1,1,1,1,1,1,1,1,1,1,1,1,1,1,1,11,11,11
28,11,11,11,11,11,11,1,1,1,1,1,1,1,1,1,1,1,1,1,1,1,11,11,11,11
28,11,11,11,11,11,1,1,1,1,1,1,11,1,1,1,1,1,1,1,1,2,11,11,11,11
28,11,11,11,11,11,11,1,1,1,1,1,1,1,1,1,1,1,1,11,11,2,11,11,11,11
28,28,11,11,11,11,11,11,11,11,11,11,11,11,11,11,11,11,11,11,11,11,11,11,11,11
28,28,28,28,11,11,11,11,11,11,11,11,11,11,11,11,11,11,11,11,11,11,11,11,11,11
endlayer

layer
0,0,0,0,0,28,28,28,28,28,28,28,28,28,28,28,28,28,28,28,0,0,0,0,0,0
0,0,0,28,28,28,28,28,11,11,11,11,11,1,11,11,11,11,11,28,28,28,28,28,28,0
0,0,28,28,28,28,28,11,11,11,11,11,11,1,11,11,11,11,11,11,1,11,28,28,28,0
0,0,28,28,28,28,11,11,11,11,11,11,11,1,11,11,11,11,11,11,1,11,11,28,28,28
0,28,28,28,28,11,11,11,11,11,1,1,1,1,1,1,11,1,1,1,1,11,11,11,28,28
0,28,28,11,11,11,11,11,1,1,1,1,1,1,1,1,1,1,1,1,1,11,11,11,11,28
0,28,28,11,11,11,1,1,1,1,1,1,1,1,1,1,1,1,1,1,1,11,11,11,11,11
0,28,28,11,11,1,1,1,1,1,1,1,1,1,1,1,1,1,1,1,1,11,11,11,11,11
0,28,28,11,11,11,1,1,1,1,1,1,1,2,2,1,1,18,18,18,1,11,11,11,11,11
28,28,11,11,11,11,11,1,1,1,1,1,1,1,2,20,15,14,14,14,13,11,11,11,11,11
28,28,28,11,11,11,11,1,1,1,1,7,57,57,57,57,57,57,31,57,1,11,11,11,11,11
28,28,28,11,11,11,11,11,1,1,1,1,1,1,25,57,57,57,57,57,1,1,1,11,11,11
28,28,11,11,11,11,11,11,11,1,1,1,1,26,57,57,57,57,57,57,1,1,1,11,11,11
28,11,11,11,11,11,11,1,1,1,1,1,1,1,3,57,1,2,1,1,1,1,1,11,11,28
28,11,11,11,11,11,11,11,1,1,1,1,1,1,1,1,2,2,2,1,1,1,1,11,11,28
28,11,11,11,11,11,11,11,1,1,1,1,1,1,1,1,1,1,1,1,1,1,11,11,11,28
0,28,28,11,11,11,11,11,1,1,1,1,1,1,1,1,1,1,1,1,1,1,11,11,11,28
0,28,28,11,11,11,11,11,1,1,1,1,11,11,1,1,1,1,1,1,1,2,2,2,11,28
0,28,28,11,11,11,11,11,11,11,11,11,11,11,11,1,1,1,1,11,11,2,2,2,11,28
0,0,28,28,11,11,11,28,11,11,11,11,11,11,11,11,11,11,11,11,11,11,11,11,28,28
0,0,0,0,28,11,11,11,11,11,11,11,28,28,11,11,28,28,28,28,28,28,28,28,28,28
endlayer

layer
0,0,0,0,0,0,0,0,0,0,0,0,0,0,0,0,0,0,0,0,0,0,0,0,0,0
0,0,0,0,0,0,0,0,28,28,28,28,28,28,28,28,28,28,28,0,0,0,0,0,0,0
0,0,0,0,0,0,0,28,28,28,28,28,28,28,28,11,11,11,11,28,28,28,0,0,0,0
0,0,0,0,0,0,28,28,11,11,11,11,11,1,11,11,11,11,11,11,1,11,11,0,0,0
0,0,0,0,0,28,28,11,11,11,1,1,1,1,1,1,11,1,1,1,1,11,11,28,0,0
0,0,0,28,28,28,11,11,1,1,1,1,1,1,1,1,1,1,1,1,1,11,11,28,28,0
0,0,0,28,11,11,1,1,1,1,1,1,1,1,1,1,1,1,1,1,1,11,11,11,28,28
0,0,0,28,11,1,1,1,1,1,1,1,1,1,1,1,1,1,1,1,1,11,11,11,11,28
0,0,0,28,11,11,1,1,1,1,1,1,1,2,2,1,1,1,1,1,1,11,11,11,11,28
58,0,28,11,11,11,11,1,1,1,1,1,1,1,2,1,12,32,32,32,12,11,11,11,11,28
0,0,0,28,11,11,11,1,1,1,7,57,57,57,57,57,57,57,33,32,1,11,11,11,11,28
0,0,0,28,35,35,11,11,1,1,1,1,1,25,57,57,57,57,57,34,1,1,1,11,11,28
0,0,28,11,35,16,11,11,11,1,1,1,26,57,57,57,57,30,37,36,1,1,1,11,28,28
0,28,11,11,35,16,11,11,1,1,1,1,1,1,3,57,1,1,1,1,1,1,1,11,28,0
0,28,11,11,11,11,11,11,1,1,1,1,1,1,1,1,1,1,1,1,1,1,11,28,28,0
0,28,28,11,11,11,11,11,1,1,1,1,1,1,1,1,1,1,1,1,1,1,11,28,28,0
0,0,0,28,11,11,11,11,1,1,1,1,1,1,1,1,1,1,1,1,1,1,28,28,28,0
0,0,0,28,28,11,11,11,1,1,1,1,11,11,1,1,1,1,1,1,1,1,2,2,28,0
0,0,0,28,28,28,11,11,11,11,11,11,11,11,11,1,1,1,1,28,28,28,2,2,28,0
0,0,0,0,28,28,28,0,11,11,11,11,28,28,28,28,28,28,28,28,28,28,28,28,0,0
0,0,0,0,0,28,28,28,28,28,28,28,0,0,28,28,0,0,0,0,0,0,0,0,0,0
endlayer

layer
0,0,0,0,0,0,0,0,0,0,0,0,0,0,0,0,0,0,0,0,0,0,0,0,0,0
0,0,0,0,0,0,0,0,58,0,0,0,0,0,0,0,0,0,0,0,0,0,0,0,0,0
0,0,0,0,0,0,0,0,0,0,0,0,0,0,0,28,28,28,28,0,0,0,0,0,0,0
0,0,0,0,0,0,0,0,28,28,28,28,28,28,28,28,28,11,11,11,1,28,28,0,0,0
0,0,0,0,0,0,0,28,28,11,1,1,1,1,1,1,11,1,1,1,1,11,28,0,0,0
0,0,0,0,0,0,28,28,1,1,1,1,1,1,1,1,1,1,1,1,1,11,28,0,0,0
0,0,0,0,28,28,1,1,1,1,1,1,1,1,1,1,1,1,1,1,1,11,11,28,0,0
0,0,0,0,28,1,1,1,1,1,1,1,38,1,1,1,1,1,1,1,1,11,11,28,28,0
0,0,0,0,28,11,1,1,1,1,1,38,57,38,1,1,1,1,1,1,1,11,11,11,28,0
0,0,0,28,28,11,11,1,1,12,7,57,3,57,3,1,1,1,1,1,1,11,11,11,28,0
0,0,0,0,28,28,28,1,7,57,57,57,57,57,57,57,32,1,1,1,1,11,11,11,28,0
0,0,0,0,35,35,35,35,1,1,1,1,25,57,57,57,32,1,1,1,1,1,1,28,28,0
0,0,0,16,35,16,28,28,28,16,16,26,57,57,57,57,32,39,1,1,1,1,1,28,0,0
0,0,28,16,35,16,28,28,1,1,1,1,1,1,3,37,1,1,1,1,1,1,28,28,0,0
0,0,28,16,16,16,28,28,1,1,1,1,1,1,1,1,1,1,1,1,1,1,28,0,0,0
0,0,0,28,28,28,28,11,1,1,1,1,1,1,1,1,1,1,1,1,1,1,28,0,0,0
0,0,0,0,28,28,28,11,1,1,1,1,1,1,1,1,1,1,1,1,1,1,0,0,0,0
0,0,0,0,0,28,28,28,1,1,1,1,11,11,1,1,1,1,1,1,1,0,0,0,0,0
0,0,0,0,0,0,28,28,28,11,11,11,28,28,28,1,1,1,7,0,0,0,0,0,0,0
0,0,0,0,0,0,0,28,28,28,28,28,0,0,0,0,0,0,0,0,0,0,0,0,0,0
0,0,0,0,0,0,0,0,0,0,0,0,0,0,0,0,0,0,0,0,0,0,0,0,0,0
endlayer

layer
0,0,0,0,0,0,0,0,0,0,0,0,0,0,0,0,0,0,0,0,0,0,0,0,0,0
0,0,0,0,0,0,0,0,0,0,0,0,0,0,0,0,0,0,0,0,0,0,0,0,0,0
0,0,0,0,0,0,0,0,0,0,0,0,0,0,0,0,0,0,0,0,0,0,0,0,0,0
0,0,0,0,0,0,0,0,0,0,0,0,0,0,0,0,0,28,28,28,40,0,0,0,0,0
0,0,0,0,0,0,0,0,0,28,1,1,1,1,1,1,28,1,1,1,1,28,0,0,0,0
0,0,0,0,0,0,0,0,30,1,1,1,1,1,1,1,1,1,1,1,1,28,0,0,0,0
0,0,0,0,0,0,1,1,1,1,1,1,1,1,1,1,1,1,1,1,1,28,28,0,0,0
0,0,0,0,0,1,1,1,1,1,1,1,0,1,1,1,1,1,1,1,1,28,28,0,0,0
0,0,0,0,0,28,1,1,1,1,1,41,0,41,1,1,1,1,1,1,1,11,28,28,0,0
0,0,0,0,0,28,28,1,1,3,0,0,3,0,42,1,1,1,1,1,1,11,11,28,0,0
0,0,0,0,0,0,0,0,0,0,0,0,0,0,43,39,1,1,1,1,1,2,2,28,0,0
0,0,0,0,44,24,24,24,24,24,24,24,0,0,43,39,1,1,1,1,1,1,1,0,0,0
0,0,0,0,4,0,0,0,0,0,0,0,0,0,43,39,1,1,1,1,1,1,1,0,0,0
0,0,0,0,46,0,0,0,5,12,1,1,12,1,45,1,1,1,1,1,1,1,0,0,0,0
0,0,0,0,48,0,0,47,1,1,1,1,1,1,1,1,1,1,1,1,1,1,0,0,0,0
0,0,0,0,0,0,0,28,1,1,1,1,1,1,1,1,1,1,1,1,1,1,0,0,0,0
0,0,0,0,0,0,0,28,1,1,1,2,2,1,1,1,1,1,1,1,1,0,0,0,0,0
0,0,0,0,0,58,0,0,5,1,1,2,2,28,1,1,1,1,1,1,0,0,0,0,0,0
0,0,0,0,0,0,0,0,0,28,28,28,0,0,0,5,1,1,0,0,0,0,0,0,0,0
0,0,0,0,0,0,0,0,0,0,0,0,0,0,0,0,0,0,0,0,0,0,0,0,0,0
0,0,0,0,0,0,0,0,0,0,0,0,0,0,0,0,0,0,0,0,0,0,0,0,0,0
endlayer

layer
0,0,0,0,0,0,0,0,0,0,0,0,0,0,0,0,0,0,0,0,0,0,0,0,0,0
0,0,0,0,0,0,0,0,0,0,0,0,0,0,0,0,0,0,0,0,0,0,0,0,0,0
0,0,0,0,0,0,0,0,0,0,0,0,0,0,0,0,0,0,0,0,0,0,0,0,0,0
0,0,0,0,0,0,0,0,0,0,0,0,0,0,0,0,0,0,0,0,0,0,0,0,0,0
0,0,0,0,0,0,0,0,0,0,1,1,40,28,28,28,0,40,1,1,40,0,0,0,0,0
0,0,0,0,0,0,0,0,0,40,1,1,1,1,1,1,1,1,1,1,1,0,0,0,0,0
0,0,0,0,0,0,40,1,1,1,1,1,1,1,1,1,1,1,1,1,1,0,0,0,0,0
0,0,0,0,0,40,1,1,1,1,1,2,41,1,1,1,1,1,1,1,1,0,58,0,0,0
0,0,0,0,0,0,40,1,1,1,1,49,0,41,1,1,1,1,1,1,1,2,0,0,0,0
0,0,0,0,0,0,0,40,1,3,0,0,3,0,1,1,1,1,1,1,1,2,2,0,0,0
0,0,0,0,0,0,0,0,0,0,0,0,0,0,39,1,1,1,1,1,1,2,2,0,0,0
0,0,0,0,0,0,0,0,0,0,0,0,0,0,39,1,1,1,1,1,1,1,40,0,0,0
0,0,0,0,0,0,0,0,0,0,0,0,0,0,39,1,1,1,1,1,1,1,0,0,0,0
0,0,0,0,0,0,0,0,0,3,40,40,3,1,1,1,1,1,1,1,1,1,0,0,0,0
0,0,0,0,0,0,0,0,40,1,1,1,1,1,1,1,1,1,1,1,1,40,0,0,0,0
0,0,0,0,0,0,0,0,40,1,1,1,1,1,1,1,1,1,1,1,1,0,0,0,0,0
0,0,0,0,0,0,0,0,40,1,1,1,1,1,1,1,1,1,1,1,40,0,0,0,0,0
0,0,0,0,0,0,0,0,0,40,40,40,2,0,40,1,1,1,1,40,0,0,0,0,0,0
0,0,0,0,0,0,0,0,0,0,0,0,0,0,0,0,1,7,0,0,0,0,0,0,0,0
0,0,0,0,0,0,0,0,0,0,0,0,0,0,0,0,0,0,0,0,0,0,0,0,0,0
0,0,0,0,0,0,0,0,0,0,0,0,0,0,0,0,0,0,0,0,0,0,0,0,0,0
endlayer

layer
0,0,0,0,0,0,0,0,0,0,0,0,0,0,0,0,0,0,0,0,0,0,0,0,0,0
0,0,0,0,0,0,0,0,0,0,0,0,0,0,0,0,0,0,0,0,0,0,0,0,0,0
0,0,0,0,0,0,0,0,0,0,0,0,0,0,0,0,0,0,0,0,0,0,0,0,0,0
0,0,0,0,0,0,0,0,0,0,0,0,0,0,0,0,0,0,0,0,0,0,0,0,0,0
0,0,0,0,0,0,0,0,0,0,1,40,0,0,0,0,0,0,0,0,0,0,0,0,0,0
0,0,0,0,0,0,0,0,0,0,1,1,1,1,1,40,1,1,40,40,40,0,0,0,0,0
0,0,0,0,0,0,0,0,50,2,2,2,1,1,1,1,1,1,1,1,40,0,0,0,0,0
0,0,0,0,0,0,40,1,1,1,1,2,2,1,1,1,1,1,1,1,1,0,0,0,0,0
0,0,0,0,0,0,0,5,1,1,1,1,0,1,1,1,1,1,1,1,1,0,0,0,0,0
0,0,0,0,0,0,0,0,5,3,0,0,3,17,1,1,1,1,1,1,1,2,0,0,0,0
0,0,0,0,0,0,0,0,0,0,0,0,0,51,1,1,1,1,1,1,1,1,0,0,0,0
0,0,0,0,0,0,0,0,0,0,0,31,0,0,1,1,1,1,1,1,1,40,0,0,0,0
0,0,0,0,0,0,0,0,0,0,0,0,0,0,1,1,1,1,1,1,0,0,0,0,0,0
0,0,0,0,0,0,0,0,0,3,0,0,3,1,1,1,1,1,1,1,1,0,0,0,0,0
0,0,0,0,0,0,0,0,0,40,1,1,0,1,1,1,1,1,1,1,1,0,0,0,0,0
0,0,0,0,0,0,0,0,0,40,40,1,1,1,1,1,1,1,1,1,40,0,0,0,0,0
0,0,0,0,0,0,0,0,0,0,0,0,40,1,1,1,1,1,1,40,0,0,0,0,0,0
0,0,0,0,0,0,0,0,0,0,0,0,0,0,0,40,1,1,40,0,0,0,0,0,0,0
0,0,0,0,0,0,0,0,0,0,0,0,0,0,0,0,0,0,0,0,0,0,0,0,0,0
0,0,0,0,0,0,0,0,0,0,0,0,0,0,0,0,0,0,0,0,0,0,0,0,0,0
0,0,0,0,0,0,0,0,0,0,0,0,0,0,0,0,0,0,0,0,0,0,0,0,0,0
endlayer

layer
0,0,0,0,0,0,0,0,0,0,0,0,0,0,0,0,0,0,0,0,0,0,0,0,0,0
0,0,0,0,0,0,0,0,0,0,0,0,0,0,0,0,0,0,0,0,0,0,0,0,0,0
0,0,0,0,0,0,0,0,0,0,0,0,0,0,0,0,0,0,0,0,0,0,0,0,0,0
0,0,0,0,0,0,0,0,0,0,0,0,0,0,0,0,0,0,0,0,0,0,0,0,0,0
0,0,0,0,0,0,0,0,0,0,40,0,0,0,0,0,0,0,0,0,0,0,0,0,0,0
0,0,0,0,0,0,0,0,0,0,1,1,1,7,0,0,40,40,0,0,0,0,0,0,0,0
0,0,0,0,0,0,0,0,0,0,1,1,1,1,1,1,1,1,1,40,0,0,0,0,0,0
0,0,0,0,0,0,0,0,1,1,1,1,1,1,1,1,1,1,1,1,0,0,0,0,0,0
0,0,0,0,0,0,0,0,5,1,0,1,1,1,1,1,1,1,1,1,40,0,0,0,0,0
0,0,0,0,0,0,0,0,56,53,14,14,52,1,1,1,1,1,1,1,1,0,0,0,0,0
0,0,0,0,0,0,0,0,56,43,0,0,43,1,1,1,1,1,1,1,1,40,0,0,0,0
0,0,0,0,0,0,0,0,56,43,0,33,43,1,1,1,1,1,1,1,40,0,0,0,0,0
0,0,0,0,0,0,0,0,56,43,0,0,43,1,1,1,1,1,1,1,0,0,0,0,0,0
0,0,0,0,0,0,0,0,56,45,0,0,45,1,1,1,1,1,1,40,0,0,0,0,0,0
0,0,0,0,0,0,0,0,56,0,0,0,0,1,1,1,1,1,1,0,0,0,0,0,0,0
0,0,0,0,0,0,0,0,56,56,56,56,56,56,1,1,1,1,40,0,0,0,0,0,0,0
0,0,0,0,0,0,0,0,0,0,0,0,0,0,40,1,40,0,0,0,0,0,0,0,0,0
0,0,0,0,0,0,0,0,0,0,0,0,0,0,0,0,0,0,0,0,0,0,0,0,0,0
0,0,0,0,0,0,0,0,0,0,0,0,0,0,0,0,0,0,0,0,0,0,0,0,0,0
0,0,0,0,0,0,0,0,0,0,0,0,0,0,0,0,0,0,0,0,0,0,0,0,0,0
0,0,0,0,0,0,0,0,0,0,0,0,0,0,0,0,0,0,0,0,0,0,0,0,0,0
endlayer

layer
0,0,0,0,0,0,0,0,0,0,0,0,0,0,0,0,0,0,0,0,0,0,0,0,0,0
0,0,0,0,0,0,0,0,0,0,0,0,0,0,0,0,0,0,0,0,0,0,0,0,0,0
0,0,0,0,0,0,0,0,0,0,0,0,0,0,0,0,0,0,0,0,0,0,0,0,0,0
0,0,0,0,0,0,0,0,0,0,0,0,0,0,0,0,0,0,0,0,0,0,0,0,0,0
0,0,0,0,0,0,0,0,0,0,0,0,0,0,0,0,0,0,0,0,0,0,0,0,0,0
0,0,0,0,0,0,0,0,0,0,5,40,7,0,0,0,0,0,0,0,0,0,0,0,0,0
0,0,0,0,0,0,0,0,0,0,1,1,27,0,9,1,40,40,0,0,0,0,0,0,0,0
0,0,0,0,0,0,0,0,0,9,1,1,1,30,1,1,40,40,1,40,0,0,0,0,0,0
0,0,0,0,0,0,0,0,0,55,1,1,1,1,1,1,1,1,1,1,0,0,0,0,0,0
0,0,0,0,0,0,0,0,0,55,54,54,54,1,1,1,1,1,1,1,0,0,0,0,0,0
0,0,0,0,0,0,0,0,0,55,54,54,54,1,1,1,1,1,1,1,0,0,0,0,0,0
0,0,0,0,0,0,0,0,0,55,54,54,54,1,1,1,1,1,1,1,0,0,0,0,0,0
0,0,0,0,0,0,0,0,0,55,54,54,54,1,1,1,1,1,1,40,0,0,0,0,0,0
0,0,0,0,0,0,0,0,0,55,54,54,54,1,1,1,1,0,0,0,0,0,0,0,0,0
0,0,0,0,0,0,0,0,0,55,55,55,55,55,1,40,40,0,0,0,0,0,0,0,0,0
0,0,0,0,0,0,0,0,0,0,0,0,0,0,0,0,0,0,0,0,0,0,0,0,0,0
0,0,0,0,0,0,0,0,0,0,0,0,0,0,0,0,0,0,0,0,0,0,0,0,0,0
0,0,0,0,0,0,0,0,0,0,0,0,0,0,0,0,0,0,0,0,0,0,0,0,0,0
0,0,0,0,0,0,0,0,0,0,0,0,0,0,0,0,0,0,0,0,0,0,0,0,0,0
0,0,0,0,0,0,0,0,0,0,0,0,0,0,0,0,0,0,0,0,0,0,0,0,0,0
0,0,0,0,0,0,0,0,0,0,0,0,0,0,0,0,0,0,0,0,0,0,0,0,0,0
endlayer
#

layer
0,0,0,0,0,0,0,0,0,0,0,0,0,0,0,0,0,0,0,0,0,0,0,0,0,0
0,0,0,0,0,0,0,0,0,0,0,0,0,0,0,0,0,0,0,0,0,0,0,0,0,0
0,0,0,0,0,0,0,0,0,0,0,0,0,0,0,0,0,0,0,0,0,0,0,0,0,0
0,0,0,0,0,0,0,0,0,0,0,0,0,0,0,0,0,0,0,0,0,0,0,0,0,0
0,0,0,0,0,0,0,0,0,0,0,0,0,0,0,0,0,0,0,0,0,0,0,0,0,0
0,0,0,0,0,0,0,0,0,0,0,0,0,0,0,0,0,0,0,0,0,0,0,0,0,0
0,0,0,0,0,0,0,0,0,0,40,40,60,0,9,1,0,0,0,0,0,0,0,0,0,0
0,0,0,0,0,0,0,0,0,0,40,1,1,30,1,1,0,0,40,0,0,0,0,0,0,0
0,0,0,0,0,0,0,0,0,0,40,40,40,1,1,1,1,1,40,0,0,0,0,0,0,0
0,0,0,0,0,0,0,0,0,0,0,0,0,1,1,40,1,1,1,0,0,0,0,0,0,0
0,0,0,0,0,0,0,0,0,0,0,0,0,0,40,40,1,1,40,0,0,0,0,0,0,0
0,0,0,0,0,0,0,0,0,0,0,0,0,0,0,40,40,40,0,0,0,0,0,0,0,0
0,0,0,0,0,0,0,0,0,0,0,0,0,0,0,0,0,0,0,0,0,0,0,0,0,0
0,0,0,0,0,0,0,0,0,0,0,0,0,0,0,0,0,0,0,0,0,0,0,0,0,0
0,0,0,0,0,0,0,0,0,0,0,0,0,0,0,0,0,0,0,0,0,0,0,0,0,0
0,0,0,0,0,0,0,0,0,0,0,0,0,0,0,0,0,0,0,0,0,0,0,0,0,0
0,0,0,0,0,0,0,0,0,0,0,0,0,0,0,0,0,0,0,0,0,0,0,0,0,0
0,0,0,0,0,0,0,0,0,0,0,0,0,0,0,0,0,0,0,0,0,0,0,0,0,0
0,0,0,0,0,0,0,0,0,0,0,0,0,0,0,0,0,0,0,0,0,0,0,0,0,0
0,0,0,0,0,0,0,0,0,0,0,0,0,0,0,0,0,0,0,0,0,0,0,0,0,0
0,0,0,0,0,0,0,0,0,0,0,0,0,0,0,0,0,0,0,0,0,0,0,0,0,0
endlayer
#
layer
0,0,0,0,0,0,0,0,0,0,0,0,0,0,0,0,0,0,0,0,0,0,0,0,0,0
0,0,0,0,0,0,0,0,0,0,0,0,0,0,0,0,0,0,0,0,0,0,0,0,0,0
0,0,0,0,0,0,0,0,0,0,0,0,0,0,0,0,0,0,0,0,0,0,0,0,0,0
0,0,0,0,0,0,0,0,0,0,0,0,0,0,0,0,0,0,0,0,0,0,0,0,0,0
0,0,0,0,0,0,0,0,0,0,0,0,0,0,0,0,0,0,0,0,0,0,0,0,0,0
0,0,0,0,0,0,0,0,0,0,0,0,0,0,0,0,0,0,0,0,0,0,0,0,0,0
0,0,0,0,0,0,0,0,0,0,0,0,1,1,1,22,0,0,0,0,0,0,0,0,0,0
0,0,0,0,0,0,0,0,0,0,0,0,40,1,1,40,0,0,0,0,0,0,0,0,0,0
0,0,0,0,0,0,0,0,0,0,0,0,0,1,1,40,1,1,0,0,0,0,0,0,0,0
0,0,0,0,0,0,0,0,0,0,0,0,0,1,7,0,40,40,40,0,0,0,0,0,0,0
0,0,0,0,0,0,0,0,0,0,0,0,0,0,0,0,40,40,0,0,0,0,0,0,0,0
0,0,0,0,0,0,0,0,0,0,0,0,0,0,0,0,0,0,0,0,0,0,0,0,0,0
0,0,0,0,0,0,0,0,0,0,0,0,0,0,0,0,0,0,0,0,0,0,0,0,0,0
0,0,0,0,0,0,0,0,0,0,0,0,0,0,0,0,0,0,0,0,0,0,0,0,0,0
0,0,0,0,0,0,0,0,0,0,0,0,0,0,0,0,0,0,0,0,0,0,0,0,0,0
0,0,0,0,0,0,0,0,0,0,0,0,0,0,0,0,0,0,0,0,0,0,0,0,0,0
0,0,0,0,0,0,0,0,0,0,0,0,0,0,0,0,0,0,0,0,0,0,0,0,0,0
0,0,0,0,0,0,0,0,0,0,0,0,0,0,0,0,0,0,0,0,0,0,0,0,0,0
0,0,0,0,0,0,0,0,0,0,0,0,0,0,0,0,0,0,0,0,0,0,0,0,0,0
0,0,0,0,0,0,0,0,0,0,0,0,0,0,0,0,0,0,0,0,0,0,0,0,0,0
0,0,0,0,0,0,0,0,0,0,0,0,0,0,0,0,0,0,0,0,0,0,0,0,0,0
endlayer

layer
0,0,0,0,0,0,0,0,0,0,0,0,0,0,0,0,0,0,0,0,0,0,0,0,0,0
0,0,0,0,0,0,0,0,0,0,0,0,0,0,0,0,0,0,0,0,0,0,0,0,0,0
0,0,0,0,0,0,0,0,0,0,0,0,0,0,0,0,0,0,0,0,0,0,0,0,0,0
0,0,0,0,0,0,0,0,0,0,0,0,0,0,0,0,0,0,0,0,0,0,0,0,0,0
0,0,0,0,0,0,0,0,0,0,0,0,0,0,0,0,0,0,0,0,0,0,0,0,0,0
0,0,0,0,0,0,0,0,0,0,0,0,0,0,0,0,0,0,0,0,0,0,0,0,0,0
0,0,0,0,0,0,0,0,0,0,0,0,0,1,1,0,0,0,0,0,0,0,0,0,0,0
0,0,0,0,0,0,0,0,0,0,0,0,0,1,1,0,0,0,0,0,0,0,0,0,0,0
0,0,0,0,0,0,0,0,0,0,0,0,0,1,1,0,1,1,0,0,0,0,0,0,0,0
0,0,0,0,0,0,0,0,0,0,0,0,0,0,0,0,0,0,0,0,0,0,0,0,0,0
0,0,0,0,0,0,0,0,0,0,0,0,0,0,0,0,0,0,0,0,0,0,0,0,0,0
0,0,0,0,0,0,0,0,0,0,0,0,0,0,0,0,0,0,0,0,0,0,0,0,0,0
0,0,0,0,0,0,0,0,0,0,0,0,0,0,0,0,0,0,0,0,0,0,0,0,0,0
0,0,0,0,0,0,0,0,0,0,0,0,0,0,0,0,0,0,0,0,0,0,0,0,0,0
0,0,0,0,0,0,0,0,0,0,0,0,0,0,0,0,0,0,0,0,0,0,0,0,0,0
0,0,0,0,0,0,0,0,0,0,0,0,0,0,0,0,0,0,0,0,0,0,0,0,0,0
0,0,0,0,0,0,0,0,0,0,0,0,0,0,0,0,0,0,0,0,0,0,0,0,0,0
0,0,0,0,0,0,0,0,0,0,0,0,0,0,0,0,0,0,0,0,0,0,0,0,0,0
0,0,0,0,0,0,0,0,0,0,0,0,0,0,0,0,0,0,0,0,0,0,0,0,0,0
0,0,0,0,0,0,0,0,0,0,0,0,0,0,0,0,0,0,0,0,0,0,0,0,0,0
0,0,0,0,0,0,0,0,0,0,0,0,0,0,0,0,0,0,0,0,0,0,0,0,0,0
endlayer

#
#layer
#0,0,0,0,0,0,0,0,0,0,0,0,0,0,0,0,0,0,0,0,0,0,0,0,0,0
#0,0,0,0,0,0,0,0,0,0,0,0,0,0,0,0,0,0,0,0,0,0,0,0,0,0
#0,0,0,0,0,0,0,0,0,0,0,0,0,0,0,0,0,0,0,0,0,0,0,0,0,0
#0,0,0,0,0,0,0,0,0,0,0,0,0,0,0,0,0,0,0,0,0,0,0,0,0,0
#0,0,0,0,0,0,0,0,0,0,0,0,0,0,0,0,0,0,0,0,0,0,0,0,0,0
#0,0,0,0,0,0,0,0,0,0,0,0,0,0,0,0,0,0,0,0,0,0,0,0,0,0
#0,0,0,0,0,0,0,0,0,0,0,0,0,0,0,0,0,0,0,0,0,0,0,0,0,0
#0,0,0,0,0,0,0,0,0,0,0,0,0,0,0,0,0,0,0,0,0,0,0,0,0,0
#0,0,0,0,0,0,0,0,0,0,0,0,0,0,0,0,0,0,0,0,0,0,0,0,0,0
#0,0,0,0,0,0,0,0,0,0,0,0,0,0,0,0,0,0,0,0,0,0,0,0,0,0
#0,0,0,0,0,0,0,0,0,0,0,0,0,0,0,0,0,0,0,0,0,0,0,0,0,0
#0,0,0,0,0,0,0,0,0,0,0,0,0,0,0,0,0,0,0,0,0,0,0,0,0,0
#0,0,0,0,0,0,0,0,0,0,0,0,0,0,0,0,0,0,0,0,0,0,0,0,0,0
#0,0,0,0,0,0,0,0,0,0,0,0,0,0,0,0,0,0,0,0,0,0,0,0,0,0
#0,0,0,0,0,0,0,0,0,0,0,0,0,0,0,0,0,0,0,0,0,0,0,0,0,0
#0,0,0,0,0,0,0,0,0,0,0,0,0,0,0,0,0,0,0,0,0,0,0,0,0,0
#0,0,0,0,0,0,0,0,0,0,0,0,0,0,0,0,0,0,0,0,0,0,0,0,0,0
#0,0,0,0,0,0,0,0,0,0,0,0,0,0,0,0,0,0,0,0,0,0,0,0,0,0
#0,0,0,0,0,0,0,0,0,0,0,0,0,0,0,0,0,0,0,0,0,0,0,0,0,0
#0,0,0,0,0,0,0,0,0,0,0,0,0,0,0,0,0,0,0,0,0,0,0,0,0,0
#0,0,0,0,0,0,0,0,0,0,0,0,0,0,0,0,0,0,0,0,0,0,0,0,0,0
#endlayer
#

#layer
#  0,  0,  0,  0,  0,  0,  0,  0,  0,  0,  0,  0,  0,  0,  0,  0,  0,  0,  0,  0,  0,  0,  0,  0,  0,  0
#  0,  0,  0,  0,  0,  0,  0,  0,  0,  0,  0,  0,  0,  0,  0,  0,  0,  0,  0,  0,  0,  0,  0,  0,  0,  0
#  0,  0,  0,  0,  0,  0,  0,  0,  0,  0,  0,  0,  0,  0,  0,  0,  0,  0,  0,  0,  0,  0,  0,  0,  0,  0
#  0,  0,  0,  0,  0,  0,  0,  0,  0,  0,  0,  0,  0,  0,  0,  0,  0,  0,  0,  0,  0,  0,  0,  0,  0,  0
#  0,  0,  0,  0,  0,  0,  0,  0,  0,  0,  0,  0,  0,  0,  0,  0,  0,  0,  0,  0,  0,  0,  0,  0,  0,  0
#  0,  0,  0,  0,  0,  0,  0,  0,  0,  0,  0,  0,  0,  0,  0,  0,  0,  0,  0,  0,  0,  0,  0,  0,  0,  0
#  0,  0,  0,  0,  0,  0,  0,  0,  0,  0,  0,  0,  0, 22, 62,  0,  0,  0,  0,  0,  0,  0,  0,  0,  0,  0
#  0,  0,  0,  0,  0,  0,  0,  0,  0,  0,  0,  0,  0,  1,  7,  0,  0,  0,  0,  0,  0,  0,  0,  0,  0,  0
#  0,  0,  0,  0,  0,  0,  0,  0,  0,  0,  0,  0,  0,  1, 63,  0,  5,  1,  0,  0,  0,  0,  0,  0,  0,  0
#  0,  0,  0,  0,  0,  0,  0,  0,  0,  0,  0,  0,  0,  0,  0,  0,  0,  0,  0,  0,  0,  0,  0,  0,  0,  0
#  0,  0,  0,  0,  0,  0,  0,  0,  0,  0,  0,  0,  0,  0,  0,  0,  0,  0,  0,  0,  0,  0,  0,  0,  0,  0
#  0,  0,  0,  0,  0,  0,  0,  0,  0,  0,  0,  0,  0,  0,  0,  0,  0,  0,  0,  0,  0,  0,  0,  0,  0,  0
#  0,  0,  0,  0,  0,  0,  0,  0,  0,  0,  0,  0,  0,  0,  0,  0,  0,  0,  0,  0,  0,  0,  0,  0,  0,  0
#  0,  0,  0,  0,  0,  0,  0,  0,  0,  0,  0,  0,  0,  0,  0,  0,  0,  0,  0,  0,  0,  0,  0,  0,  0,  0
#  0,  0,  0,  0,  0,  0,  0,  0,  0,  0,  0,  0,  0,  0,  0,  0,  0,  0,  0,  0,  0,  0,  0,  0,  0,  0
#  0,  0,  0,  0,  0,  0,  0,  0,  0,  0,  0,  0,  0,  0,  0,  0,  0,  0,  0,  0,  0,  0,  0,  0,  0,  0
#  0,  0,  0,  0,  0,  0,  0,  0,  0,  0,  0,  0,  0,  0,  0,  0,  0,  0,  0,  0,  0,  0,  0,  0,  0,  0
#  0,  0,  0,  0,  0,  0,  0,  0,  0,  0,  0,  0,  0,  0,  0,  0,  0,  0,  0,  0,  0,  0,  0,  0,  0,  0
#  0,  0,  0,  0,  0,  0,  0,  0,  0,  0,  0,  0,  0,  0,  0,  0,  0,  0,  0,  0,  0,  0,  0,  0,  0,  0
#  0,  0,  0,  0,  0,  0,  0,  0,  0,  0,  0,  0,  0,  0,  0,  0,  0,  0,  0,  0,  0,  0,  0,  0,  0,  0
#  0,  0,  0,  0,  0,  0,  0,  0,  0,  0,  0,  0,  0,  0,  0,  0,  0,  0,  0,  0,  0,  0,  0,  0,  0,  0
#endlayer

