
# Created by Ruins mod Ingame Parser
# authoring Player: Syndaryl

# TEMPLATE PARAMETER SETTINGS:
#
# criterion expression specifying mod ids required to load template
# may include plus (AND), minus (AND NOT), comma (OR), and parentheses
# all required mods listed must be present; no prohibited mods can be
requiredMods=
#
# likelihood this template will be chosen relative to all others
# e.g., a weight=6 template is chosen 3X as often as one with weight=2
weight=1
#
# list of dimensions in which this template may spawn, even if generic
# one or more dimension names, separated by commas (blank = all)
dimensionsToSpawnIn=
#
# list of other biomes in which this template may spawn
# biome corresponding to directory is always assumed, listed or not
# generic templates should leave this list empty
biomesToSpawnIn=
#
# criterion expression specifying types of biome where template spawns
# this is in addition to those explicitly listed as biomesToSpawnIn
# generic templates should leave this list empty
biomeTypesToSpawnIn=HOT,SPARSE,DRY,SANDY,WASTELAND
#
# list of biomes in which this template may not spawn
# takes precedence over biomeTypesToSpawnIn, but NOT biomesToSpawnIn
# should be empty if biomeTypesToSpawnIn is empty
biomesToNotSpawnIn=
#
# depth template is pushed down into the surface when built
# offset is min/max range of random additional bury depth
embed_into_distance=0
random_height_offset=-2,1
#
# whitelist/blacklist of block states on which template may be built
# specify one, not both; leave the other empty (both empty = allow all)
# CAUTION: THE DEFAULTS ONLY APPLY TO NON-FLOWING LAVA AND WATER VARIANTS)
acceptable_target_blocks={Name:"minecraft:sandstone"},{Name:"minecraft:sand"}
unacceptable_target_blocks=
#
# size of template (#layers, #rows per layer, #blocks per row)
dimensions=10,15,15
#
# max number of missing blocks allowed in surface beneath template
allowable_overhang=0
#
# depth/height limit affected by terrain leveling
# also maximum bumpiness tolerated in surface beneath template
max_leveling=2
#
# padding applied to all sides of template horizontal footprint
# expands area affected by terrain leveling (-1 = no leveling)
leveling_buffer=3
#
# do not rotate template randomly when built (1 = no rotation)
preventRotation=0
#
# treat water/lava blocks as air and protect them from rule0 (1 = yes)
preserve_water=0
preserve_lava=0
#
# minimum distance this template must have from instances of itself
uniqueMinDistance=0
#
# min/max distances this template can be from world spawn (0 = no limit)
# only applies to overworld--i.e., dimension 0
spawnMinDistance=0
spawnMaxDistance=0
#
# other template built nearby whenever this one is
# syntax: <name>;<relativeX>;<maxYdifference>;<relativeZ>[;<chance>]
# may be used more than once to specify multiple neighbors
adjoining_template=

rule1={Name:"minecraft:sandstone"}
rule2={Name:"minecraft:cut_sandstone"}
rule3={Name:"minecraft:smooth_red_sandstone"}
rule4={Ruins:{entity:{ForgeData:{LootTable:"minecraft:chests/abandoned_mineshaft"},Items:[]}},Properties:{waterlogged:"false",facing:"west",type:"single"},Name:"minecraft:chest"},{Ruins:{entity:{ForgeData:{LootTable:"minecraft:chests/stronghold_library"},Items:[]}},Properties:{waterlogged:"false",facing:"west",type:"single"},Name:"minecraft:trapped_chest"},{Ruins:{entity:{ForgeData:{LootTable:"minecraft:chests/stronghold_crossing"},Items:[]}},Properties:{waterlogged:"false",facing:"west",type:"single"},Name:"minecraft:trapped_chest"},{Ruins:{entity:{ForgeData:{LootTable:"minecraft:chests/buried_treasure"},Items:[]}},Properties:{waterlogged:"false",facing:"west",type:"single"},Name:"minecraft:trapped_chest"}
rule5={Name:"air"}
rule6={Ruins:{entity:{ignore_players:0b,MaxNearbyEntities:6s,RequiredPlayerRange:16s,ignore_cap:0b,ignore_conditions:0b,SpawnCount:4s,SpawnData:{id:"minecraft:husk"},MaxSpawnDelay:800s,Delay:0s,redstone_control:0b,SpawnRange:4s,MinSpawnDelay:200s,SpawnPotentials:[{Entity:{id:"minecraft:husk"},Weight:10},{Entity:{id:"minecraft:skeleton"},Weight:1},{Entity:{id:"minecraft:zombie"},Weight:1}]}},Name:"minecraft:spawner"}
rule7={Name:"minecraft:obsidian"}
rule8={Name:"minecraft:chiseled_sandstone"}

layer
1,1,1,1,1,1,1,1,1,1,1,1,1,1,1
1,1,1,1,1,1,1,2,1,1,1,1,1,1,1
1,1,1,1,1,1,2,3,1,1,1,1,1,1,1
1,1,1,1,1,2,3,3,3,1,1,1,1,1,1
1,1,1,1,2,3,3,3,3,3,1,1,1,1,1
1,1,1,2,3,3,3,3,3,3,3,1,1,1,1
1,1,2,3,3,3,3,3,3,3,3,3,2,1,1
1,2,3,3,3,3,3,4,3,3,3,3,3,2,1
1,1,2,3,3,3,3,3,3,3,3,3,2,1,1
1,1,1,2,3,3,3,3,3,3,3,2,1,1,1
1,1,1,1,2,3,3,3,3,3,2,1,1,1,1
1,1,1,1,1,2,3,3,3,2,1,1,1,1,1
1,1,1,1,1,1,2,3,2,1,1,1,1,1,1
1,1,1,1,1,1,1,2,1,1,1,1,1,1,1
1,1,1,1,1,1,1,1,1,1,1,1,1,1,1
endlayer

layer
1,1,1,1,1,1,1,1,1,1,1,1,1,1,1
1,1,1,1,1,1,1,2,1,1,1,1,1,1,1
1,1,1,1,1,1,2,5,2,1,1,1,1,1,1
1,1,1,1,1,2,5,5,5,2,1,1,1,1,1
1,1,1,1,2,5,5,5,5,5,2,1,1,1,1
1,1,1,2,5,5,5,5,5,5,5,2,1,1,1
1,1,2,5,5,5,5,5,5,5,5,5,2,1,1
1,2,5,5,5,5,5,6,5,5,5,5,5,2,1
1,1,2,5,5,5,5,5,5,5,5,5,2,1,1
1,1,1,2,5,5,5,5,5,5,5,2,1,1,1
1,1,1,1,2,5,5,5,5,5,2,1,1,1,1
1,1,1,1,1,2,5,5,5,2,1,1,1,1,1
1,1,1,1,1,1,2,5,2,1,1,1,1,1,1
1,1,1,1,1,1,1,2,1,1,1,1,1,1,1
1,1,1,1,1,1,1,1,1,1,1,1,1,1,1
endlayer

layer
2,2,2,2,2,2,2,2,2,2,2,2,2,2,2
2,2,2,2,2,2,2,2,2,2,2,2,2,2,2
2,2,2,2,2,2,2,5,2,2,2,2,2,2,2
2,2,2,2,2,2,5,5,5,2,2,2,2,2,2
2,2,2,2,2,5,5,5,5,5,2,2,2,2,2
2,2,2,2,5,5,5,5,5,5,5,2,2,2,2
2,2,2,5,5,5,5,5,5,5,5,5,2,2,2
2,2,5,5,5,5,5,7,5,5,5,5,5,2,2
2,2,2,5,5,5,5,5,5,5,5,5,2,2,2
2,2,2,2,5,5,5,5,5,5,5,2,2,2,2
2,2,2,2,2,5,5,5,5,5,2,2,2,2,2
2,2,2,2,2,2,5,5,5,2,2,2,2,2,2
2,2,2,2,2,2,2,5,2,2,2,2,2,2,2
2,2,2,2,2,2,2,2,2,2,2,2,2,2,2
2,2,2,2,2,2,2,2,2,2,2,2,2,2,2
endlayer

layer
0,0,0,0,0,0,0,0,0,0,0,0,0,0,0
0,8,8,8,8,8,8,8,8,8,8,8,8,8,0
0,8,1,1,1,1,1,5,1,1,1,1,1,8,0
0,8,1,1,1,1,5,5,5,1,1,1,1,8,0
0,8,1,1,1,5,5,5,5,5,1,1,1,8,0
0,8,1,1,5,5,5,5,5,5,5,1,1,8,0
0,8,1,5,5,5,5,5,5,5,5,5,1,8,0
0,8,5,5,5,5,5,5,5,5,5,5,5,8,0
0,8,1,5,5,5,5,5,5,5,5,5,1,8,0
0,8,1,1,5,5,5,5,5,5,5,1,1,8,0
0,8,1,1,1,5,5,5,5,5,1,1,1,8,0
0,8,1,1,1,1,5,5,5,1,1,1,1,8,0
0,8,1,1,1,1,1,5,1,1,1,1,1,8,0
0,8,8,8,8,8,8,8,8,8,8,8,8,8,0
0,0,0,0,0,0,0,0,0,0,0,0,0,0,0
endlayer

layer
0,0,0,0,0,0,0,0,0,0,0,0,0,0,0
0,0,0,0,0,0,0,0,0,0,0,0,0,0,0
0,0,2,2,2,2,2,2,2,2,2,2,2,0,0
0,0,2,1,1,1,1,5,1,1,1,1,2,0,0
0,0,2,1,1,1,5,5,5,1,1,1,2,0,0
0,0,2,1,1,5,5,5,5,5,1,1,2,0,0
0,0,2,1,5,5,5,5,5,5,5,1,2,0,0
0,0,2,5,5,5,5,5,5,5,5,5,2,0,0
0,0,2,1,5,5,5,5,5,5,5,1,2,0,0
0,0,2,1,1,5,5,5,5,5,1,1,2,0,0
0,0,2,1,1,1,5,5,5,1,1,1,2,0,0
0,0,2,1,1,1,1,5,1,1,1,1,2,0,0
0,0,2,2,2,2,2,2,2,2,2,2,2,0,0
0,0,0,0,0,0,0,0,0,0,0,0,0,0,0
0,0,0,0,0,0,0,0,0,0,0,0,0,0,0
endlayer

layer
0,0,0,0,0,0,0,0,0,0,0,0,0,0,0
0,0,0,0,0,0,0,0,0,0,0,0,0,0,0
0,0,0,0,0,0,0,0,0,0,0,0,0,0,0
0,0,0,8,8,8,8,8,8,8,8,8,0,0,0
0,0,0,8,1,1,1,5,1,1,1,8,0,0,0
0,0,0,8,1,1,5,5,5,1,1,8,0,0,0
0,0,0,8,1,5,5,5,5,5,1,8,0,0,0
0,0,0,8,5,5,5,5,5,5,5,8,0,0,0
0,0,0,8,1,5,5,5,5,5,1,8,0,0,0
0,0,0,8,1,1,5,5,5,1,1,8,0,0,0
0,0,0,8,1,1,1,5,1,1,1,8,0,0,0
0,0,0,8,8,8,8,8,8,8,8,8,0,0,0
0,0,0,0,0,0,0,0,0,0,0,0,0,0,0
0,0,0,0,0,0,0,0,0,0,0,0,0,0,0
0,0,0,0,0,0,0,0,0,0,0,0,0,0,0
endlayer

layer
0,0,0,0,0,0,0,0,0,0,0,0,0,0,0
0,0,0,0,0,0,0,0,0,0,0,0,0,0,0
0,0,0,0,0,0,0,0,0,0,0,0,0,0,0
0,0,0,0,0,0,0,0,0,0,0,0,0,0,0
0,0,0,0,2,2,2,2,2,2,2,0,0,0,0
0,0,0,0,2,1,1,5,1,1,2,0,0,0,0
0,0,0,0,2,1,5,5,5,1,2,0,0,0,0
0,0,0,0,2,5,5,5,5,5,2,0,0,0,0
0,0,0,0,2,1,5,5,5,1,2,0,0,0,0
0,0,0,0,2,1,1,5,1,1,2,0,0,0,0
0,0,0,0,2,2,2,2,2,2,2,0,0,0,0
0,0,0,0,0,0,0,0,0,0,0,0,0,0,0
0,0,0,0,0,0,0,0,0,0,0,0,0,0,0
0,0,0,0,0,0,0,0,0,0,0,0,0,0,0
0,0,0,0,0,0,0,0,0,0,0,0,0,0,0
endlayer

layer
0,0,0,0,0,0,0,0,0,0,0,0,0,0,0
0,0,0,0,0,0,0,0,0,0,0,0,0,0,0
0,0,0,0,0,0,0,0,0,0,0,0,0,0,0
0,0,0,0,0,0,0,0,0,0,0,0,0,0,0
0,0,0,0,0,0,0,0,0,0,0,0,0,0,0
0,0,0,0,0,8,8,8,8,8,0,0,0,0,0
0,0,0,0,0,8,1,5,1,8,0,0,0,0,0
0,0,0,0,0,8,5,5,5,8,0,0,0,0,0
0,0,0,0,0,8,1,5,1,8,0,0,0,0,0
0,0,0,0,0,8,8,8,8,8,0,0,0,0,0
0,0,0,0,0,0,0,0,0,0,0,0,0,0,0
0,0,0,0,0,0,0,0,0,0,0,0,0,0,0
0,0,0,0,0,0,0,0,0,0,0,0,0,0,0
0,0,0,0,0,0,0,0,0,0,0,0,0,0,0
0,0,0,0,0,0,0,0,0,0,0,0,0,0,0
endlayer

layer
0,0,0,0,0,0,0,0,0,0,0,0,0,0,0
0,0,0,0,0,0,0,0,0,0,0,0,0,0,0
0,0,0,0,0,0,0,0,0,0,0,0,0,0,0
0,0,0,0,0,0,0,0,0,0,0,0,0,0,0
0,0,0,0,0,0,0,0,0,0,0,0,0,0,0
0,0,0,0,0,0,0,0,0,0,0,0,0,0,0
0,0,0,0,0,0,2,2,2,0,0,0,0,0,0
0,0,0,0,0,0,2,2,2,0,0,0,0,0,0
0,0,0,0,0,0,2,2,2,0,0,0,0,0,0
0,0,0,0,0,0,0,0,0,0,0,0,0,0,0
0,0,0,0,0,0,0,0,0,0,0,0,0,0,0
0,0,0,0,0,0,0,0,0,0,0,0,0,0,0
0,0,0,0,0,0,0,0,0,0,0,0,0,0,0
0,0,0,0,0,0,0,0,0,0,0,0,0,0,0
0,0,0,0,0,0,0,0,0,0,0,0,0,0,0
endlayer

layer
0,0,0,0,0,0,0,0,0,0,0,0,0,0,0
0,0,0,0,0,0,0,0,0,0,0,0,0,0,0
0,0,0,0,0,0,0,0,0,0,0,0,0,0,0
0,0,0,0,0,0,0,0,0,0,0,0,0,0,0
0,0,0,0,0,0,0,0,0,0,0,0,0,0,0
0,0,0,0,0,0,0,0,0,0,0,0,0,0,0
0,0,0,0,0,0,0,0,0,0,0,0,0,0,0
0,0,0,0,0,0,0,8,0,0,0,0,0,0,0
0,0,0,0,0,0,0,0,0,0,0,0,0,0,0
0,0,0,0,0,0,0,0,0,0,0,0,0,0,0
0,0,0,0,0,0,0,0,0,0,0,0,0,0,0
0,0,0,0,0,0,0,0,0,0,0,0,0,0,0
0,0,0,0,0,0,0,0,0,0,0,0,0,0,0
0,0,0,0,0,0,0,0,0,0,0,0,0,0,0
0,0,0,0,0,0,0,0,0,0,0,0,0,0,0
endlayer

